[2025-08-18T20:59:36.528+0000] {taskinstance.py:1979} INFO - Dependencies all met for dep_context=non-requeueable deps ti=<TaskInstance: customer_churn_pipeline.dvc_add_commit_model manual__2025-08-18T20:58:35.634632+00:00 [queued]>
[2025-08-18T20:59:36.540+0000] {taskinstance.py:1979} INFO - Dependencies all met for dep_context=requeueable deps ti=<TaskInstance: customer_churn_pipeline.dvc_add_commit_model manual__2025-08-18T20:58:35.634632+00:00 [queued]>
[2025-08-18T20:59:36.542+0000] {taskinstance.py:2193} INFO - Starting attempt 1 of 1
[2025-08-18T20:59:36.559+0000] {taskinstance.py:2217} INFO - Executing <Task(BashOperator): dvc_add_commit_model> on 2025-08-18 20:58:35.634632+00:00
[2025-08-18T20:59:36.565+0000] {standard_task_runner.py:60} INFO - Started process 1562 to run task
[2025-08-18T20:59:36.570+0000] {standard_task_runner.py:87} INFO - Running: ['***', 'tasks', 'run', 'customer_churn_pipeline', 'dvc_add_commit_model', 'manual__2025-08-18T20:58:35.634632+00:00', '--job-id', '33', '--raw', '--subdir', 'DAGS_FOLDER/customer_churn_pipeline_dag.py', '--cfg-path', '/tmp/tmp1o1ennnc']
[2025-08-18T20:59:36.573+0000] {standard_task_runner.py:88} INFO - Job 33: Subtask dvc_add_commit_model
[2025-08-18T20:59:36.638+0000] {task_command.py:423} INFO - Running <TaskInstance: customer_churn_pipeline.dvc_add_commit_model manual__2025-08-18T20:58:35.634632+00:00 [running]> on host 2e4674d7276b
[2025-08-18T20:59:36.721+0000] {taskinstance.py:2513} INFO - Exporting env vars: AIRFLOW_CTX_DAG_OWNER='***' AIRFLOW_CTX_DAG_ID='customer_churn_pipeline' AIRFLOW_CTX_TASK_ID='dvc_add_commit_model' AIRFLOW_CTX_EXECUTION_DATE='2025-08-18T20:58:35.634632+00:00' AIRFLOW_CTX_TRY_NUMBER='1' AIRFLOW_CTX_DAG_RUN_ID='manual__2025-08-18T20:58:35.634632+00:00'
[2025-08-18T20:59:36.723+0000] {subprocess.py:63} INFO - Tmp dir root location: /tmp
[2025-08-18T20:59:36.724+0000] {subprocess.py:75} INFO - Running command: ['/usr/bin/bash', '-c', "cd /opt/***/Customer_Churn_Prediction_Pipeline && dvc add models/churn_model.pkl && git add models/churn_model.pkl.dvc && git commit -m 'Add trained model to DVC'"]
[2025-08-18T20:59:36.737+0000] {subprocess.py:86} INFO - Output:
[2025-08-18T20:59:46.806+0000] {subprocess.py:93} INFO - 
[2025-08-18T20:59:46.807+0000] {subprocess.py:93} INFO - To track the changes with git, run:
[2025-08-18T20:59:46.808+0000] {subprocess.py:93} INFO - 
[2025-08-18T20:59:46.809+0000] {subprocess.py:93} INFO - 	git add models/churn_model.pkl.dvc models/.gitignore
[2025-08-18T20:59:46.809+0000] {subprocess.py:93} INFO - 
[2025-08-18T20:59:46.810+0000] {subprocess.py:93} INFO - To enable auto staging, run:
[2025-08-18T20:59:46.810+0000] {subprocess.py:93} INFO - 
[2025-08-18T20:59:46.811+0000] {subprocess.py:93} INFO - 	dvc config core.autostage true
[2025-08-18T20:59:47.047+0000] {subprocess.py:93} INFO - fatal: detected dubious ownership in repository at '/opt/***/Customer_Churn_Prediction_Pipeline'
[2025-08-18T20:59:47.048+0000] {subprocess.py:93} INFO - To add an exception for this directory, call:
[2025-08-18T20:59:47.050+0000] {subprocess.py:93} INFO - 
[2025-08-18T20:59:47.051+0000] {subprocess.py:93} INFO - 	git config --global --add safe.directory /opt/***/Customer_Churn_Prediction_Pipeline
[2025-08-18T20:59:47.052+0000] {subprocess.py:97} INFO - Command exited with return code 128
[2025-08-18T20:59:47.072+0000] {taskinstance.py:2731} ERROR - Task failed with exception
Traceback (most recent call last):
  File "/home/airflow/.local/lib/python3.8/site-packages/airflow/models/taskinstance.py", line 444, in _execute_task
    result = _execute_callable(context=context, **execute_callable_kwargs)
  File "/home/airflow/.local/lib/python3.8/site-packages/airflow/models/taskinstance.py", line 414, in _execute_callable
    return execute_callable(context=context, **execute_callable_kwargs)
  File "/home/airflow/.local/lib/python3.8/site-packages/airflow/operators/bash.py", line 212, in execute
    raise AirflowException(
airflow.exceptions.AirflowException: Bash command failed. The command returned a non-zero exit code 128.
[2025-08-18T20:59:47.078+0000] {taskinstance.py:1149} INFO - Marking task as FAILED. dag_id=customer_churn_pipeline, task_id=dvc_add_commit_model, execution_date=20250818T205835, start_date=20250818T205936, end_date=20250818T205947
[2025-08-18T20:59:47.101+0000] {standard_task_runner.py:107} ERROR - Failed to execute job 33 for task dvc_add_commit_model (Bash command failed. The command returned a non-zero exit code 128.; 1562)
[2025-08-18T20:59:47.145+0000] {local_task_job_runner.py:234} INFO - Task exited with return code 1
[2025-08-18T20:59:47.164+0000] {taskinstance.py:3312} INFO - 0 downstream tasks scheduled from follow-on schedule check
