[2025-08-18T20:26:48.889+0000] {taskinstance.py:1979} INFO - Dependencies all met for dep_context=non-requeueable deps ti=<TaskInstance: customer_churn_pipeline.dvc_pull_data manual__2025-08-18T20:26:47.860361+00:00 [queued]>
[2025-08-18T20:26:48.903+0000] {taskinstance.py:1979} INFO - Dependencies all met for dep_context=requeueable deps ti=<TaskInstance: customer_churn_pipeline.dvc_pull_data manual__2025-08-18T20:26:47.860361+00:00 [queued]>
[2025-08-18T20:26:48.905+0000] {taskinstance.py:2193} INFO - Starting attempt 1 of 1
[2025-08-18T20:26:48.928+0000] {taskinstance.py:2217} INFO - Executing <Task(BashOperator): dvc_pull_data> on 2025-08-18 20:26:47.860361+00:00
[2025-08-18T20:26:48.937+0000] {standard_task_runner.py:60} INFO - Started process 211 to run task
[2025-08-18T20:26:48.947+0000] {standard_task_runner.py:87} INFO - Running: ['***', 'tasks', 'run', 'customer_churn_pipeline', 'dvc_pull_data', 'manual__2025-08-18T20:26:47.860361+00:00', '--job-id', '3', '--raw', '--subdir', 'DAGS_FOLDER/customer_churn_pipeline_dag.py', '--cfg-path', '/tmp/tmp0e9i89ss']
[2025-08-18T20:26:48.952+0000] {standard_task_runner.py:88} INFO - Job 3: Subtask dvc_pull_data
[2025-08-18T20:26:49.048+0000] {task_command.py:423} INFO - Running <TaskInstance: customer_churn_pipeline.dvc_pull_data manual__2025-08-18T20:26:47.860361+00:00 [running]> on host 2e4674d7276b
[2025-08-18T20:26:49.160+0000] {taskinstance.py:2513} INFO - Exporting env vars: AIRFLOW_CTX_DAG_OWNER='***' AIRFLOW_CTX_DAG_ID='customer_churn_pipeline' AIRFLOW_CTX_TASK_ID='dvc_pull_data' AIRFLOW_CTX_EXECUTION_DATE='2025-08-18T20:26:47.860361+00:00' AIRFLOW_CTX_TRY_NUMBER='1' AIRFLOW_CTX_DAG_RUN_ID='manual__2025-08-18T20:26:47.860361+00:00'
[2025-08-18T20:26:49.163+0000] {subprocess.py:63} INFO - Tmp dir root location: /tmp
[2025-08-18T20:26:49.166+0000] {subprocess.py:75} INFO - Running command: ['/usr/bin/bash', '-c', 'cd /opt/***/Customer_Churn_Prediction_Pipeline && dvc pull --force']
[2025-08-18T20:26:49.180+0000] {subprocess.py:86} INFO - Output:
[2025-08-18T20:26:52.375+0000] {subprocess.py:93} INFO - ERROR: failed to pull data from the cloud - Unable to acquire lock. Most likely another DVC process is running or was terminated abruptly. Check the page <https://dvc.org/doc/user-guide/troubleshooting#lock-issue> for other possible reasons and to learn how to resolve this.
[2025-08-18T20:26:52.558+0000] {subprocess.py:97} INFO - Command exited with return code 1
[2025-08-18T20:26:52.578+0000] {taskinstance.py:2731} ERROR - Task failed with exception
Traceback (most recent call last):
  File "/home/airflow/.local/lib/python3.8/site-packages/airflow/models/taskinstance.py", line 444, in _execute_task
    result = _execute_callable(context=context, **execute_callable_kwargs)
  File "/home/airflow/.local/lib/python3.8/site-packages/airflow/models/taskinstance.py", line 414, in _execute_callable
    return execute_callable(context=context, **execute_callable_kwargs)
  File "/home/airflow/.local/lib/python3.8/site-packages/airflow/operators/bash.py", line 212, in execute
    raise AirflowException(
airflow.exceptions.AirflowException: Bash command failed. The command returned a non-zero exit code 1.
[2025-08-18T20:26:52.583+0000] {taskinstance.py:1149} INFO - Marking task as FAILED. dag_id=customer_churn_pipeline, task_id=dvc_pull_data, execution_date=20250818T202647, start_date=20250818T202648, end_date=20250818T202652
[2025-08-18T20:26:52.602+0000] {standard_task_runner.py:107} ERROR - Failed to execute job 3 for task dvc_pull_data (Bash command failed. The command returned a non-zero exit code 1.; 211)
[2025-08-18T20:26:52.616+0000] {local_task_job_runner.py:234} INFO - Task exited with return code 1
[2025-08-18T20:26:52.648+0000] {taskinstance.py:3312} INFO - 0 downstream tasks scheduled from follow-on schedule check
