[2025-08-19T17:52:06.890+0000] {taskinstance.py:1979} INFO - Dependencies all met for dep_context=non-requeueable deps ti=<TaskInstance: customer_churn_pipeline.model_training manual__2025-08-19T17:51:23.774653+00:00 [queued]>
[2025-08-19T17:52:06.920+0000] {taskinstance.py:1979} INFO - Dependencies all met for dep_context=requeueable deps ti=<TaskInstance: customer_churn_pipeline.model_training manual__2025-08-19T17:51:23.774653+00:00 [queued]>
[2025-08-19T17:52:06.922+0000] {taskinstance.py:2193} INFO - Starting attempt 1 of 1
[2025-08-19T17:52:06.963+0000] {taskinstance.py:2217} INFO - Executing <Task(BashOperator): model_training> on 2025-08-19 17:51:23.774653+00:00
[2025-08-19T17:52:06.977+0000] {standard_task_runner.py:60} INFO - Started process 1162 to run task
[2025-08-19T17:52:06.998+0000] {standard_task_runner.py:87} INFO - Running: ['***', 'tasks', 'run', 'customer_churn_pipeline', 'model_training', 'manual__2025-08-19T17:51:23.774653+00:00', '--job-id', '31', '--raw', '--subdir', 'DAGS_FOLDER/customer_churn_pipeline_dag.py', '--cfg-path', '/tmp/tmp0v4mfefh']
[2025-08-19T17:52:07.018+0000] {standard_task_runner.py:88} INFO - Job 31: Subtask model_training
[2025-08-19T17:52:07.183+0000] {task_command.py:423} INFO - Running <TaskInstance: customer_churn_pipeline.model_training manual__2025-08-19T17:51:23.774653+00:00 [running]> on host dc08f7cf7bac
[2025-08-19T17:52:07.328+0000] {taskinstance.py:2513} INFO - Exporting env vars: AIRFLOW_CTX_DAG_OWNER='***' AIRFLOW_CTX_DAG_ID='customer_churn_pipeline' AIRFLOW_CTX_TASK_ID='model_training' AIRFLOW_CTX_EXECUTION_DATE='2025-08-19T17:51:23.774653+00:00' AIRFLOW_CTX_TRY_NUMBER='1' AIRFLOW_CTX_DAG_RUN_ID='manual__2025-08-19T17:51:23.774653+00:00'
[2025-08-19T17:52:07.330+0000] {subprocess.py:63} INFO - Tmp dir root location: /tmp
[2025-08-19T17:52:07.332+0000] {subprocess.py:75} INFO - Running command: ['/usr/bin/bash', '-c', 'cd /opt/***/Customer_Churn_Prediction_Pipeline && python src/train_model.py']
[2025-08-19T17:52:07.350+0000] {subprocess.py:86} INFO - Output:
[2025-08-19T17:52:11.306+0000] {subprocess.py:93} INFO - 2025-08-19 17:52:11,303 WARNING Malformed experiment '3c451db2cddf461b9fa24b573ecdc116'. Detailed error Yaml file '/opt/***/Customer_Churn_Prediction_Pipeline/mlruns/3c451db2cddf461b9fa24b573ecdc116/meta.yaml' does not exist.
[2025-08-19T17:52:11.308+0000] {subprocess.py:93} INFO - Traceback (most recent call last):
[2025-08-19T17:52:11.309+0000] {subprocess.py:93} INFO -   File "/home/***/.local/lib/python3.8/site-packages/mlflow/store/tracking/file_store.py", line 327, in search_experiments
[2025-08-19T17:52:11.311+0000] {subprocess.py:93} INFO -     exp = self._get_experiment(exp_id, view_type)
[2025-08-19T17:52:11.312+0000] {subprocess.py:93} INFO -   File "/home/***/.local/lib/python3.8/site-packages/mlflow/store/tracking/file_store.py", line 421, in _get_experiment
[2025-08-19T17:52:11.313+0000] {subprocess.py:93} INFO -     meta = FileStore._read_yaml(experiment_dir, FileStore.META_DATA_FILE_NAME)
[2025-08-19T17:52:11.314+0000] {subprocess.py:93} INFO -   File "/home/***/.local/lib/python3.8/site-packages/mlflow/store/tracking/file_store.py", line 1367, in _read_yaml
[2025-08-19T17:52:11.315+0000] {subprocess.py:93} INFO -     return _read_helper(root, file_name, attempts_remaining=retries)
[2025-08-19T17:52:11.316+0000] {subprocess.py:93} INFO -   File "/home/***/.local/lib/python3.8/site-packages/mlflow/store/tracking/file_store.py", line 1360, in _read_helper
[2025-08-19T17:52:11.317+0000] {subprocess.py:93} INFO -     result = read_yaml(root, file_name)
[2025-08-19T17:52:11.318+0000] {subprocess.py:93} INFO -   File "/home/***/.local/lib/python3.8/site-packages/mlflow/utils/file_utils.py", line 309, in read_yaml
[2025-08-19T17:52:11.319+0000] {subprocess.py:93} INFO -     raise MissingConfigException(f"Yaml file '{file_path}' does not exist.")
[2025-08-19T17:52:11.320+0000] {subprocess.py:93} INFO - mlflow.exceptions.MissingConfigException: Yaml file '/opt/***/Customer_Churn_Prediction_Pipeline/mlruns/3c451db2cddf461b9fa24b573ecdc116/meta.yaml' does not exist.
[2025-08-19T17:52:11.393+0000] {subprocess.py:93} INFO - 2025-08-19 17:52:11,392 WARNING Malformed experiment '66a6a96d2c6e463cbcf97c942dce679d'. Detailed error Yaml file '/opt/***/Customer_Churn_Prediction_Pipeline/mlruns/66a6a96d2c6e463cbcf97c942dce679d/meta.yaml' does not exist.
[2025-08-19T17:52:11.395+0000] {subprocess.py:93} INFO - Traceback (most recent call last):
[2025-08-19T17:52:11.397+0000] {subprocess.py:93} INFO -   File "/home/***/.local/lib/python3.8/site-packages/mlflow/store/tracking/file_store.py", line 327, in search_experiments
[2025-08-19T17:52:11.398+0000] {subprocess.py:93} INFO -     exp = self._get_experiment(exp_id, view_type)
[2025-08-19T17:52:11.399+0000] {subprocess.py:93} INFO -   File "/home/***/.local/lib/python3.8/site-packages/mlflow/store/tracking/file_store.py", line 421, in _get_experiment
[2025-08-19T17:52:11.401+0000] {subprocess.py:93} INFO -     meta = FileStore._read_yaml(experiment_dir, FileStore.META_DATA_FILE_NAME)
[2025-08-19T17:52:11.402+0000] {subprocess.py:93} INFO -   File "/home/***/.local/lib/python3.8/site-packages/mlflow/store/tracking/file_store.py", line 1367, in _read_yaml
[2025-08-19T17:52:11.404+0000] {subprocess.py:93} INFO -     return _read_helper(root, file_name, attempts_remaining=retries)
[2025-08-19T17:52:11.405+0000] {subprocess.py:93} INFO -   File "/home/***/.local/lib/python3.8/site-packages/mlflow/store/tracking/file_store.py", line 1360, in _read_helper
[2025-08-19T17:52:11.406+0000] {subprocess.py:93} INFO -     result = read_yaml(root, file_name)
[2025-08-19T17:52:11.407+0000] {subprocess.py:93} INFO -   File "/home/***/.local/lib/python3.8/site-packages/mlflow/utils/file_utils.py", line 309, in read_yaml
[2025-08-19T17:52:11.408+0000] {subprocess.py:93} INFO -     raise MissingConfigException(f"Yaml file '{file_path}' does not exist.")
[2025-08-19T17:52:11.410+0000] {subprocess.py:93} INFO - mlflow.exceptions.MissingConfigException: Yaml file '/opt/***/Customer_Churn_Prediction_Pipeline/mlruns/66a6a96d2c6e463cbcf97c942dce679d/meta.yaml' does not exist.
[2025-08-19T17:52:11.411+0000] {subprocess.py:93} INFO - 2025-08-19 17:52:11,409 WARNING Malformed experiment '758f77ef4c794795bdfdff4c02503bcc'. Detailed error Yaml file '/opt/***/Customer_Churn_Prediction_Pipeline/mlruns/758f77ef4c794795bdfdff4c02503bcc/meta.yaml' does not exist.
[2025-08-19T17:52:11.412+0000] {subprocess.py:93} INFO - Traceback (most recent call last):
[2025-08-19T17:52:11.413+0000] {subprocess.py:93} INFO -   File "/home/***/.local/lib/python3.8/site-packages/mlflow/store/tracking/file_store.py", line 327, in search_experiments
[2025-08-19T17:52:11.415+0000] {subprocess.py:93} INFO -     exp = self._get_experiment(exp_id, view_type)
[2025-08-19T17:52:11.416+0000] {subprocess.py:93} INFO -   File "/home/***/.local/lib/python3.8/site-packages/mlflow/store/tracking/file_store.py", line 421, in _get_experiment
[2025-08-19T17:52:11.417+0000] {subprocess.py:93} INFO -     meta = FileStore._read_yaml(experiment_dir, FileStore.META_DATA_FILE_NAME)
[2025-08-19T17:52:11.418+0000] {subprocess.py:93} INFO -   File "/home/***/.local/lib/python3.8/site-packages/mlflow/store/tracking/file_store.py", line 1367, in _read_yaml
[2025-08-19T17:52:11.419+0000] {subprocess.py:93} INFO -     return _read_helper(root, file_name, attempts_remaining=retries)
[2025-08-19T17:52:11.421+0000] {subprocess.py:93} INFO -   File "/home/***/.local/lib/python3.8/site-packages/mlflow/store/tracking/file_store.py", line 1360, in _read_helper
[2025-08-19T17:52:11.422+0000] {subprocess.py:93} INFO -     result = read_yaml(root, file_name)
[2025-08-19T17:52:11.423+0000] {subprocess.py:93} INFO -   File "/home/***/.local/lib/python3.8/site-packages/mlflow/utils/file_utils.py", line 309, in read_yaml
[2025-08-19T17:52:11.424+0000] {subprocess.py:93} INFO -     raise MissingConfigException(f"Yaml file '{file_path}' does not exist.")
[2025-08-19T17:52:11.425+0000] {subprocess.py:93} INFO - mlflow.exceptions.MissingConfigException: Yaml file '/opt/***/Customer_Churn_Prediction_Pipeline/mlruns/758f77ef4c794795bdfdff4c02503bcc/meta.yaml' does not exist.
[2025-08-19T17:52:11.427+0000] {subprocess.py:93} INFO - 2025-08-19 17:52:11,423 WARNING Malformed experiment '7a4c300b24d14505ba7f4df32748abf9'. Detailed error Yaml file '/opt/***/Customer_Churn_Prediction_Pipeline/mlruns/7a4c300b24d14505ba7f4df32748abf9/meta.yaml' does not exist.
[2025-08-19T17:52:11.428+0000] {subprocess.py:93} INFO - Traceback (most recent call last):
[2025-08-19T17:52:11.429+0000] {subprocess.py:93} INFO -   File "/home/***/.local/lib/python3.8/site-packages/mlflow/store/tracking/file_store.py", line 327, in search_experiments
[2025-08-19T17:52:11.430+0000] {subprocess.py:93} INFO -     exp = self._get_experiment(exp_id, view_type)
[2025-08-19T17:52:11.431+0000] {subprocess.py:93} INFO -   File "/home/***/.local/lib/python3.8/site-packages/mlflow/store/tracking/file_store.py", line 421, in _get_experiment
[2025-08-19T17:52:11.432+0000] {subprocess.py:93} INFO -     meta = FileStore._read_yaml(experiment_dir, FileStore.META_DATA_FILE_NAME)
[2025-08-19T17:52:11.434+0000] {subprocess.py:93} INFO -   File "/home/***/.local/lib/python3.8/site-packages/mlflow/store/tracking/file_store.py", line 1367, in _read_yaml
[2025-08-19T17:52:11.435+0000] {subprocess.py:93} INFO -     return _read_helper(root, file_name, attempts_remaining=retries)
[2025-08-19T17:52:11.436+0000] {subprocess.py:93} INFO -   File "/home/***/.local/lib/python3.8/site-packages/mlflow/store/tracking/file_store.py", line 1360, in _read_helper
[2025-08-19T17:52:11.439+0000] {subprocess.py:93} INFO -     result = read_yaml(root, file_name)
[2025-08-19T17:52:11.440+0000] {subprocess.py:93} INFO -   File "/home/***/.local/lib/python3.8/site-packages/mlflow/utils/file_utils.py", line 309, in read_yaml
[2025-08-19T17:52:11.442+0000] {subprocess.py:93} INFO -     raise MissingConfigException(f"Yaml file '{file_path}' does not exist.")
[2025-08-19T17:52:11.443+0000] {subprocess.py:93} INFO - mlflow.exceptions.MissingConfigException: Yaml file '/opt/***/Customer_Churn_Prediction_Pipeline/mlruns/7a4c300b24d14505ba7f4df32748abf9/meta.yaml' does not exist.
[2025-08-19T17:52:11.444+0000] {subprocess.py:93} INFO - 2025-08-19 17:52:11,436 WARNING Malformed experiment '9f8a2292aea24d39a6b035889d38fb72'. Detailed error Yaml file '/opt/***/Customer_Churn_Prediction_Pipeline/mlruns/9f8a2292aea24d39a6b035889d38fb72/meta.yaml' does not exist.
[2025-08-19T17:52:11.445+0000] {subprocess.py:93} INFO - Traceback (most recent call last):
[2025-08-19T17:52:11.446+0000] {subprocess.py:93} INFO -   File "/home/***/.local/lib/python3.8/site-packages/mlflow/store/tracking/file_store.py", line 327, in search_experiments
[2025-08-19T17:52:11.447+0000] {subprocess.py:93} INFO -     exp = self._get_experiment(exp_id, view_type)
[2025-08-19T17:52:11.448+0000] {subprocess.py:93} INFO -   File "/home/***/.local/lib/python3.8/site-packages/mlflow/store/tracking/file_store.py", line 421, in _get_experiment
[2025-08-19T17:52:11.450+0000] {subprocess.py:93} INFO -     meta = FileStore._read_yaml(experiment_dir, FileStore.META_DATA_FILE_NAME)
[2025-08-19T17:52:11.451+0000] {subprocess.py:93} INFO -   File "/home/***/.local/lib/python3.8/site-packages/mlflow/store/tracking/file_store.py", line 1367, in _read_yaml
[2025-08-19T17:52:11.452+0000] {subprocess.py:93} INFO -     return _read_helper(root, file_name, attempts_remaining=retries)
[2025-08-19T17:52:11.453+0000] {subprocess.py:93} INFO -   File "/home/***/.local/lib/python3.8/site-packages/mlflow/store/tracking/file_store.py", line 1360, in _read_helper
[2025-08-19T17:52:11.454+0000] {subprocess.py:93} INFO -     result = read_yaml(root, file_name)
[2025-08-19T17:52:11.455+0000] {subprocess.py:93} INFO -   File "/home/***/.local/lib/python3.8/site-packages/mlflow/utils/file_utils.py", line 309, in read_yaml
[2025-08-19T17:52:11.457+0000] {subprocess.py:93} INFO -     raise MissingConfigException(f"Yaml file '{file_path}' does not exist.")
[2025-08-19T17:52:11.458+0000] {subprocess.py:93} INFO - mlflow.exceptions.MissingConfigException: Yaml file '/opt/***/Customer_Churn_Prediction_Pipeline/mlruns/9f8a2292aea24d39a6b035889d38fb72/meta.yaml' does not exist.
[2025-08-19T17:52:11.460+0000] {subprocess.py:93} INFO - 2025-08-19 17:52:11,450 WARNING Malformed experiment 'b682dba240844ed68344d97d245b4459'. Detailed error Yaml file '/opt/***/Customer_Churn_Prediction_Pipeline/mlruns/b682dba240844ed68344d97d245b4459/meta.yaml' does not exist.
[2025-08-19T17:52:11.461+0000] {subprocess.py:93} INFO - Traceback (most recent call last):
[2025-08-19T17:52:11.462+0000] {subprocess.py:93} INFO -   File "/home/***/.local/lib/python3.8/site-packages/mlflow/store/tracking/file_store.py", line 327, in search_experiments
[2025-08-19T17:52:11.463+0000] {subprocess.py:93} INFO -     exp = self._get_experiment(exp_id, view_type)
[2025-08-19T17:52:11.464+0000] {subprocess.py:93} INFO -   File "/home/***/.local/lib/python3.8/site-packages/mlflow/store/tracking/file_store.py", line 421, in _get_experiment
[2025-08-19T17:52:11.464+0000] {subprocess.py:93} INFO -     meta = FileStore._read_yaml(experiment_dir, FileStore.META_DATA_FILE_NAME)
[2025-08-19T17:52:11.465+0000] {subprocess.py:93} INFO -   File "/home/***/.local/lib/python3.8/site-packages/mlflow/store/tracking/file_store.py", line 1367, in _read_yaml
[2025-08-19T17:52:11.466+0000] {subprocess.py:93} INFO -     return _read_helper(root, file_name, attempts_remaining=retries)
[2025-08-19T17:52:11.467+0000] {subprocess.py:93} INFO -   File "/home/***/.local/lib/python3.8/site-packages/mlflow/store/tracking/file_store.py", line 1360, in _read_helper
[2025-08-19T17:52:11.467+0000] {subprocess.py:93} INFO -     result = read_yaml(root, file_name)
[2025-08-19T17:52:11.468+0000] {subprocess.py:93} INFO -   File "/home/***/.local/lib/python3.8/site-packages/mlflow/utils/file_utils.py", line 309, in read_yaml
[2025-08-19T17:52:11.469+0000] {subprocess.py:93} INFO -     raise MissingConfigException(f"Yaml file '{file_path}' does not exist.")
[2025-08-19T17:52:11.470+0000] {subprocess.py:93} INFO - mlflow.exceptions.MissingConfigException: Yaml file '/opt/***/Customer_Churn_Prediction_Pipeline/mlruns/b682dba240844ed68344d97d245b4459/meta.yaml' does not exist.
[2025-08-19T17:52:11.470+0000] {subprocess.py:93} INFO - 2025-08-19 17:52:11,463 WARNING Malformed experiment 'e45a2c3f2fe5435bb5ee5c51f9930955'. Detailed error Yaml file '/opt/***/Customer_Churn_Prediction_Pipeline/mlruns/e45a2c3f2fe5435bb5ee5c51f9930955/meta.yaml' does not exist.
[2025-08-19T17:52:11.471+0000] {subprocess.py:93} INFO - Traceback (most recent call last):
[2025-08-19T17:52:11.472+0000] {subprocess.py:93} INFO -   File "/home/***/.local/lib/python3.8/site-packages/mlflow/store/tracking/file_store.py", line 327, in search_experiments
[2025-08-19T17:52:11.473+0000] {subprocess.py:93} INFO -     exp = self._get_experiment(exp_id, view_type)
[2025-08-19T17:52:11.474+0000] {subprocess.py:93} INFO -   File "/home/***/.local/lib/python3.8/site-packages/mlflow/store/tracking/file_store.py", line 421, in _get_experiment
[2025-08-19T17:52:11.475+0000] {subprocess.py:93} INFO -     meta = FileStore._read_yaml(experiment_dir, FileStore.META_DATA_FILE_NAME)
[2025-08-19T17:52:11.476+0000] {subprocess.py:93} INFO -   File "/home/***/.local/lib/python3.8/site-packages/mlflow/store/tracking/file_store.py", line 1367, in _read_yaml
[2025-08-19T17:52:11.477+0000] {subprocess.py:93} INFO -     return _read_helper(root, file_name, attempts_remaining=retries)
[2025-08-19T17:52:11.478+0000] {subprocess.py:93} INFO -   File "/home/***/.local/lib/python3.8/site-packages/mlflow/store/tracking/file_store.py", line 1360, in _read_helper
[2025-08-19T17:52:11.479+0000] {subprocess.py:93} INFO -     result = read_yaml(root, file_name)
[2025-08-19T17:52:11.480+0000] {subprocess.py:93} INFO -   File "/home/***/.local/lib/python3.8/site-packages/mlflow/utils/file_utils.py", line 309, in read_yaml
[2025-08-19T17:52:11.480+0000] {subprocess.py:93} INFO -     raise MissingConfigException(f"Yaml file '{file_path}' does not exist.")
[2025-08-19T17:52:11.481+0000] {subprocess.py:93} INFO - mlflow.exceptions.MissingConfigException: Yaml file '/opt/***/Customer_Churn_Prediction_Pipeline/mlruns/e45a2c3f2fe5435bb5ee5c51f9930955/meta.yaml' does not exist.
[2025-08-19T17:52:11.543+0000] {subprocess.py:93} INFO - 2025-08-19 17:52:11,543 WARNING Malformed experiment '3c451db2cddf461b9fa24b573ecdc116'. Detailed error Yaml file '/opt/***/Customer_Churn_Prediction_Pipeline/mlruns/3c451db2cddf461b9fa24b573ecdc116/meta.yaml' does not exist.
[2025-08-19T17:52:11.544+0000] {subprocess.py:93} INFO - Traceback (most recent call last):
[2025-08-19T17:52:11.545+0000] {subprocess.py:93} INFO -   File "/home/***/.local/lib/python3.8/site-packages/mlflow/store/tracking/file_store.py", line 327, in search_experiments
[2025-08-19T17:52:11.546+0000] {subprocess.py:93} INFO -     exp = self._get_experiment(exp_id, view_type)
[2025-08-19T17:52:11.548+0000] {subprocess.py:93} INFO -   File "/home/***/.local/lib/python3.8/site-packages/mlflow/store/tracking/file_store.py", line 421, in _get_experiment
[2025-08-19T17:52:11.549+0000] {subprocess.py:93} INFO -     meta = FileStore._read_yaml(experiment_dir, FileStore.META_DATA_FILE_NAME)
[2025-08-19T17:52:11.550+0000] {subprocess.py:93} INFO -   File "/home/***/.local/lib/python3.8/site-packages/mlflow/store/tracking/file_store.py", line 1367, in _read_yaml
[2025-08-19T17:52:11.551+0000] {subprocess.py:93} INFO -     return _read_helper(root, file_name, attempts_remaining=retries)
[2025-08-19T17:52:11.552+0000] {subprocess.py:93} INFO -   File "/home/***/.local/lib/python3.8/site-packages/mlflow/store/tracking/file_store.py", line 1360, in _read_helper
[2025-08-19T17:52:11.553+0000] {subprocess.py:93} INFO -     result = read_yaml(root, file_name)
[2025-08-19T17:52:11.554+0000] {subprocess.py:93} INFO -   File "/home/***/.local/lib/python3.8/site-packages/mlflow/utils/file_utils.py", line 309, in read_yaml
[2025-08-19T17:52:11.555+0000] {subprocess.py:93} INFO -     raise MissingConfigException(f"Yaml file '{file_path}' does not exist.")
[2025-08-19T17:52:11.556+0000] {subprocess.py:93} INFO - mlflow.exceptions.MissingConfigException: Yaml file '/opt/***/Customer_Churn_Prediction_Pipeline/mlruns/3c451db2cddf461b9fa24b573ecdc116/meta.yaml' does not exist.
[2025-08-19T17:52:11.600+0000] {subprocess.py:93} INFO - 2025-08-19 17:52:11,600 WARNING Malformed experiment '66a6a96d2c6e463cbcf97c942dce679d'. Detailed error Yaml file '/opt/***/Customer_Churn_Prediction_Pipeline/mlruns/66a6a96d2c6e463cbcf97c942dce679d/meta.yaml' does not exist.
[2025-08-19T17:52:11.602+0000] {subprocess.py:93} INFO - Traceback (most recent call last):
[2025-08-19T17:52:11.603+0000] {subprocess.py:93} INFO -   File "/home/***/.local/lib/python3.8/site-packages/mlflow/store/tracking/file_store.py", line 327, in search_experiments
[2025-08-19T17:52:11.604+0000] {subprocess.py:93} INFO -     exp = self._get_experiment(exp_id, view_type)
[2025-08-19T17:52:11.606+0000] {subprocess.py:93} INFO -   File "/home/***/.local/lib/python3.8/site-packages/mlflow/store/tracking/file_store.py", line 421, in _get_experiment
[2025-08-19T17:52:11.607+0000] {subprocess.py:93} INFO -     meta = FileStore._read_yaml(experiment_dir, FileStore.META_DATA_FILE_NAME)
[2025-08-19T17:52:11.609+0000] {subprocess.py:93} INFO -   File "/home/***/.local/lib/python3.8/site-packages/mlflow/store/tracking/file_store.py", line 1367, in _read_yaml
[2025-08-19T17:52:11.610+0000] {subprocess.py:93} INFO -     return _read_helper(root, file_name, attempts_remaining=retries)
[2025-08-19T17:52:11.610+0000] {subprocess.py:93} INFO -   File "/home/***/.local/lib/python3.8/site-packages/mlflow/store/tracking/file_store.py", line 1360, in _read_helper
[2025-08-19T17:52:11.611+0000] {subprocess.py:93} INFO -     result = read_yaml(root, file_name)
[2025-08-19T17:52:11.612+0000] {subprocess.py:93} INFO -   File "/home/***/.local/lib/python3.8/site-packages/mlflow/utils/file_utils.py", line 309, in read_yaml
[2025-08-19T17:52:11.613+0000] {subprocess.py:93} INFO -     raise MissingConfigException(f"Yaml file '{file_path}' does not exist.")
[2025-08-19T17:52:11.614+0000] {subprocess.py:93} INFO - mlflow.exceptions.MissingConfigException: Yaml file '/opt/***/Customer_Churn_Prediction_Pipeline/mlruns/66a6a96d2c6e463cbcf97c942dce679d/meta.yaml' does not exist.
[2025-08-19T17:52:11.615+0000] {subprocess.py:93} INFO - 2025-08-19 17:52:11,614 WARNING Malformed experiment '758f77ef4c794795bdfdff4c02503bcc'. Detailed error Yaml file '/opt/***/Customer_Churn_Prediction_Pipeline/mlruns/758f77ef4c794795bdfdff4c02503bcc/meta.yaml' does not exist.
[2025-08-19T17:52:11.616+0000] {subprocess.py:93} INFO - Traceback (most recent call last):
[2025-08-19T17:52:11.617+0000] {subprocess.py:93} INFO -   File "/home/***/.local/lib/python3.8/site-packages/mlflow/store/tracking/file_store.py", line 327, in search_experiments
[2025-08-19T17:52:11.618+0000] {subprocess.py:93} INFO -     exp = self._get_experiment(exp_id, view_type)
[2025-08-19T17:52:11.619+0000] {subprocess.py:93} INFO -   File "/home/***/.local/lib/python3.8/site-packages/mlflow/store/tracking/file_store.py", line 421, in _get_experiment
[2025-08-19T17:52:11.621+0000] {subprocess.py:93} INFO -     meta = FileStore._read_yaml(experiment_dir, FileStore.META_DATA_FILE_NAME)
[2025-08-19T17:52:11.622+0000] {subprocess.py:93} INFO -   File "/home/***/.local/lib/python3.8/site-packages/mlflow/store/tracking/file_store.py", line 1367, in _read_yaml
[2025-08-19T17:52:11.623+0000] {subprocess.py:93} INFO -     return _read_helper(root, file_name, attempts_remaining=retries)
[2025-08-19T17:52:11.624+0000] {subprocess.py:93} INFO -   File "/home/***/.local/lib/python3.8/site-packages/mlflow/store/tracking/file_store.py", line 1360, in _read_helper
[2025-08-19T17:52:11.625+0000] {subprocess.py:93} INFO -     result = read_yaml(root, file_name)
[2025-08-19T17:52:11.626+0000] {subprocess.py:93} INFO -   File "/home/***/.local/lib/python3.8/site-packages/mlflow/utils/file_utils.py", line 309, in read_yaml
[2025-08-19T17:52:11.627+0000] {subprocess.py:93} INFO -     raise MissingConfigException(f"Yaml file '{file_path}' does not exist.")
[2025-08-19T17:52:11.628+0000] {subprocess.py:93} INFO - mlflow.exceptions.MissingConfigException: Yaml file '/opt/***/Customer_Churn_Prediction_Pipeline/mlruns/758f77ef4c794795bdfdff4c02503bcc/meta.yaml' does not exist.
[2025-08-19T17:52:11.628+0000] {subprocess.py:93} INFO - 2025-08-19 17:52:11,626 WARNING Malformed experiment '7a4c300b24d14505ba7f4df32748abf9'. Detailed error Yaml file '/opt/***/Customer_Churn_Prediction_Pipeline/mlruns/7a4c300b24d14505ba7f4df32748abf9/meta.yaml' does not exist.
[2025-08-19T17:52:11.630+0000] {subprocess.py:93} INFO - Traceback (most recent call last):
[2025-08-19T17:52:11.630+0000] {subprocess.py:93} INFO -   File "/home/***/.local/lib/python3.8/site-packages/mlflow/store/tracking/file_store.py", line 327, in search_experiments
[2025-08-19T17:52:11.631+0000] {subprocess.py:93} INFO -     exp = self._get_experiment(exp_id, view_type)
[2025-08-19T17:52:11.632+0000] {subprocess.py:93} INFO -   File "/home/***/.local/lib/python3.8/site-packages/mlflow/store/tracking/file_store.py", line 421, in _get_experiment
[2025-08-19T17:52:11.633+0000] {subprocess.py:93} INFO -     meta = FileStore._read_yaml(experiment_dir, FileStore.META_DATA_FILE_NAME)
[2025-08-19T17:52:11.634+0000] {subprocess.py:93} INFO -   File "/home/***/.local/lib/python3.8/site-packages/mlflow/store/tracking/file_store.py", line 1367, in _read_yaml
[2025-08-19T17:52:11.635+0000] {subprocess.py:93} INFO -     return _read_helper(root, file_name, attempts_remaining=retries)
[2025-08-19T17:52:11.636+0000] {subprocess.py:93} INFO -   File "/home/***/.local/lib/python3.8/site-packages/mlflow/store/tracking/file_store.py", line 1360, in _read_helper
[2025-08-19T17:52:11.637+0000] {subprocess.py:93} INFO -     result = read_yaml(root, file_name)
[2025-08-19T17:52:11.638+0000] {subprocess.py:93} INFO -   File "/home/***/.local/lib/python3.8/site-packages/mlflow/utils/file_utils.py", line 309, in read_yaml
[2025-08-19T17:52:11.640+0000] {subprocess.py:93} INFO -     raise MissingConfigException(f"Yaml file '{file_path}' does not exist.")
[2025-08-19T17:52:11.641+0000] {subprocess.py:93} INFO - mlflow.exceptions.MissingConfigException: Yaml file '/opt/***/Customer_Churn_Prediction_Pipeline/mlruns/7a4c300b24d14505ba7f4df32748abf9/meta.yaml' does not exist.
[2025-08-19T17:52:11.642+0000] {subprocess.py:93} INFO - 2025-08-19 17:52:11,636 WARNING Malformed experiment '9f8a2292aea24d39a6b035889d38fb72'. Detailed error Yaml file '/opt/***/Customer_Churn_Prediction_Pipeline/mlruns/9f8a2292aea24d39a6b035889d38fb72/meta.yaml' does not exist.
[2025-08-19T17:52:11.643+0000] {subprocess.py:93} INFO - Traceback (most recent call last):
[2025-08-19T17:52:11.644+0000] {subprocess.py:93} INFO -   File "/home/***/.local/lib/python3.8/site-packages/mlflow/store/tracking/file_store.py", line 327, in search_experiments
[2025-08-19T17:52:11.645+0000] {subprocess.py:93} INFO -     exp = self._get_experiment(exp_id, view_type)
[2025-08-19T17:52:11.646+0000] {subprocess.py:93} INFO -   File "/home/***/.local/lib/python3.8/site-packages/mlflow/store/tracking/file_store.py", line 421, in _get_experiment
[2025-08-19T17:52:11.647+0000] {subprocess.py:93} INFO -     meta = FileStore._read_yaml(experiment_dir, FileStore.META_DATA_FILE_NAME)
[2025-08-19T17:52:11.648+0000] {subprocess.py:93} INFO -   File "/home/***/.local/lib/python3.8/site-packages/mlflow/store/tracking/file_store.py", line 1367, in _read_yaml
[2025-08-19T17:52:11.648+0000] {subprocess.py:93} INFO -     return _read_helper(root, file_name, attempts_remaining=retries)
[2025-08-19T17:52:11.649+0000] {subprocess.py:93} INFO -   File "/home/***/.local/lib/python3.8/site-packages/mlflow/store/tracking/file_store.py", line 1360, in _read_helper
[2025-08-19T17:52:11.650+0000] {subprocess.py:93} INFO -     result = read_yaml(root, file_name)
[2025-08-19T17:52:11.651+0000] {subprocess.py:93} INFO -   File "/home/***/.local/lib/python3.8/site-packages/mlflow/utils/file_utils.py", line 309, in read_yaml
[2025-08-19T17:52:11.653+0000] {subprocess.py:93} INFO -     raise MissingConfigException(f"Yaml file '{file_path}' does not exist.")
[2025-08-19T17:52:11.654+0000] {subprocess.py:93} INFO - mlflow.exceptions.MissingConfigException: Yaml file '/opt/***/Customer_Churn_Prediction_Pipeline/mlruns/9f8a2292aea24d39a6b035889d38fb72/meta.yaml' does not exist.
[2025-08-19T17:52:11.655+0000] {subprocess.py:93} INFO - 2025-08-19 17:52:11,648 WARNING Malformed experiment 'b682dba240844ed68344d97d245b4459'. Detailed error Yaml file '/opt/***/Customer_Churn_Prediction_Pipeline/mlruns/b682dba240844ed68344d97d245b4459/meta.yaml' does not exist.
[2025-08-19T17:52:11.657+0000] {subprocess.py:93} INFO - Traceback (most recent call last):
[2025-08-19T17:52:11.659+0000] {subprocess.py:93} INFO -   File "/home/***/.local/lib/python3.8/site-packages/mlflow/store/tracking/file_store.py", line 327, in search_experiments
[2025-08-19T17:52:11.660+0000] {subprocess.py:93} INFO -     exp = self._get_experiment(exp_id, view_type)
[2025-08-19T17:52:11.661+0000] {subprocess.py:93} INFO -   File "/home/***/.local/lib/python3.8/site-packages/mlflow/store/tracking/file_store.py", line 421, in _get_experiment
[2025-08-19T17:52:11.662+0000] {subprocess.py:93} INFO -     meta = FileStore._read_yaml(experiment_dir, FileStore.META_DATA_FILE_NAME)
[2025-08-19T17:52:11.663+0000] {subprocess.py:93} INFO -   File "/home/***/.local/lib/python3.8/site-packages/mlflow/store/tracking/file_store.py", line 1367, in _read_yaml
[2025-08-19T17:52:11.664+0000] {subprocess.py:93} INFO -     return _read_helper(root, file_name, attempts_remaining=retries)
[2025-08-19T17:52:11.665+0000] {subprocess.py:93} INFO -   File "/home/***/.local/lib/python3.8/site-packages/mlflow/store/tracking/file_store.py", line 1360, in _read_helper
[2025-08-19T17:52:11.666+0000] {subprocess.py:93} INFO -     result = read_yaml(root, file_name)
[2025-08-19T17:52:11.667+0000] {subprocess.py:93} INFO -   File "/home/***/.local/lib/python3.8/site-packages/mlflow/utils/file_utils.py", line 309, in read_yaml
[2025-08-19T17:52:11.668+0000] {subprocess.py:93} INFO -     raise MissingConfigException(f"Yaml file '{file_path}' does not exist.")
[2025-08-19T17:52:11.669+0000] {subprocess.py:93} INFO - mlflow.exceptions.MissingConfigException: Yaml file '/opt/***/Customer_Churn_Prediction_Pipeline/mlruns/b682dba240844ed68344d97d245b4459/meta.yaml' does not exist.
[2025-08-19T17:52:11.670+0000] {subprocess.py:93} INFO - 2025-08-19 17:52:11,661 WARNING Malformed experiment 'e45a2c3f2fe5435bb5ee5c51f9930955'. Detailed error Yaml file '/opt/***/Customer_Churn_Prediction_Pipeline/mlruns/e45a2c3f2fe5435bb5ee5c51f9930955/meta.yaml' does not exist.
[2025-08-19T17:52:11.671+0000] {subprocess.py:93} INFO - Traceback (most recent call last):
[2025-08-19T17:52:11.672+0000] {subprocess.py:93} INFO -   File "/home/***/.local/lib/python3.8/site-packages/mlflow/store/tracking/file_store.py", line 327, in search_experiments
[2025-08-19T17:52:11.673+0000] {subprocess.py:93} INFO -     exp = self._get_experiment(exp_id, view_type)
[2025-08-19T17:52:11.675+0000] {subprocess.py:93} INFO -   File "/home/***/.local/lib/python3.8/site-packages/mlflow/store/tracking/file_store.py", line 421, in _get_experiment
[2025-08-19T17:52:11.676+0000] {subprocess.py:93} INFO -     meta = FileStore._read_yaml(experiment_dir, FileStore.META_DATA_FILE_NAME)
[2025-08-19T17:52:11.678+0000] {subprocess.py:93} INFO -   File "/home/***/.local/lib/python3.8/site-packages/mlflow/store/tracking/file_store.py", line 1367, in _read_yaml
[2025-08-19T17:52:11.679+0000] {subprocess.py:93} INFO -     return _read_helper(root, file_name, attempts_remaining=retries)
[2025-08-19T17:52:11.680+0000] {subprocess.py:93} INFO -   File "/home/***/.local/lib/python3.8/site-packages/mlflow/store/tracking/file_store.py", line 1360, in _read_helper
[2025-08-19T17:52:11.681+0000] {subprocess.py:93} INFO -     result = read_yaml(root, file_name)
[2025-08-19T17:52:11.682+0000] {subprocess.py:93} INFO -   File "/home/***/.local/lib/python3.8/site-packages/mlflow/utils/file_utils.py", line 309, in read_yaml
[2025-08-19T17:52:11.683+0000] {subprocess.py:93} INFO -     raise MissingConfigException(f"Yaml file '{file_path}' does not exist.")
[2025-08-19T17:52:11.684+0000] {subprocess.py:93} INFO - mlflow.exceptions.MissingConfigException: Yaml file '/opt/***/Customer_Churn_Prediction_Pipeline/mlruns/e45a2c3f2fe5435bb5ee5c51f9930955/meta.yaml' does not exist.
[2025-08-19T17:52:11.684+0000] {subprocess.py:93} INFO - 2025-08-19 17:52:11,664 INFO Loading features and target from feature store...
[2025-08-19T17:52:11.685+0000] {subprocess.py:93} INFO - 2025-08-19 17:52:11,664 INFO Connecting to SQLite DB at data/features/churn_features.db
[2025-08-19T17:52:11.686+0000] {subprocess.py:93} INFO - 2025-08-19 17:52:11,683 INFO Available tables: ['churn_features']
[2025-08-19T17:52:11.990+0000] {subprocess.py:93} INFO - 2025-08-19 17:52:11,989 INFO Retrieved 7032 rows and 36 columns from table churn_features
[2025-08-19T17:52:11.992+0000] {subprocess.py:93} INFO - 2025-08-19 17:52:11,992 INFO Found target column 'Churn'. Processing...
[2025-08-19T17:52:11.993+0000] {subprocess.py:93} INFO - 2025-08-19 17:52:11,992 INFO Raw target column stats:
[2025-08-19T17:52:11.994+0000] {subprocess.py:93} INFO - 2025-08-19 17:52:11,992 INFO   - Type: float64
[2025-08-19T17:52:11.995+0000] {subprocess.py:93} INFO - 2025-08-19 17:52:11,993 INFO   - Unique values: [-0.601663392508594, 1.6620589061112205]
[2025-08-19T17:52:11.996+0000] {subprocess.py:93} INFO - 2025-08-19 17:52:11,995 INFO   - Value counts:
[2025-08-19T17:52:11.997+0000] {subprocess.py:93} INFO - -0.601663    5163
[2025-08-19T17:52:11.998+0000] {subprocess.py:93} INFO -  1.662059    1869
[2025-08-19T17:52:11.999+0000] {subprocess.py:93} INFO - Name: Churn, dtype: int64
[2025-08-19T17:52:12.000+0000] {subprocess.py:93} INFO - 2025-08-19 17:52:11,997 INFO Original target values before normalization: -0.601663    5163
[2025-08-19T17:52:12.001+0000] {subprocess.py:93} INFO -  1.662059    1869
[2025-08-19T17:52:12.002+0000] {subprocess.py:93} INFO - Name: Churn, dtype: int64
[2025-08-19T17:52:12.003+0000] {subprocess.py:93} INFO - 2025-08-19 17:52:11,997 INFO Original target dtype: float64
[2025-08-19T17:52:12.004+0000] {subprocess.py:93} INFO - 2025-08-19 17:52:11,998 INFO Unique numeric values in target: [-0.601663392508594, 1.6620589061112205]
[2025-08-19T17:52:12.006+0000] {subprocess.py:93} INFO - 2025-08-19 17:52:11,998 INFO Binary target with values [-0.601663392508594, 1.6620589061112205]. Mapping to (0,1).
[2025-08-19T17:52:12.008+0000] {subprocess.py:93} INFO - 2025-08-19 17:52:11,999 INFO Mapped -0.601663392508594→0, 1.6620589061112205→1
[2025-08-19T17:52:12.009+0000] {subprocess.py:93} INFO - 2025-08-19 17:52:12,000 INFO Final normalized target stats:
[2025-08-19T17:52:12.010+0000] {subprocess.py:93} INFO - 2025-08-19 17:52:12,001 INFO   - Unique values: [0, 1]
[2025-08-19T17:52:12.011+0000] {subprocess.py:93} INFO - 2025-08-19 17:52:12,002 INFO   - Value counts:
[2025-08-19T17:52:12.011+0000] {subprocess.py:93} INFO - 0    5163
[2025-08-19T17:52:12.012+0000] {subprocess.py:93} INFO - 1    1869
[2025-08-19T17:52:12.013+0000] {subprocess.py:93} INFO - Name: Churn, dtype: int64
[2025-08-19T17:52:12.014+0000] {subprocess.py:93} INFO - 2025-08-19 17:52:12,002 INFO Features shape before dtype fix: (7032, 35), Target shape: (7032,)
[2025-08-19T17:52:12.029+0000] {subprocess.py:93} INFO - 2025-08-19 17:52:12,029 INFO Features dtypes after fix:
[2025-08-19T17:52:12.030+0000] {subprocess.py:93} INFO - gender                                   float64
[2025-08-19T17:52:12.031+0000] {subprocess.py:93} INFO - SeniorCitizen                            float64
[2025-08-19T17:52:12.032+0000] {subprocess.py:93} INFO - Partner                                  float64
[2025-08-19T17:52:12.033+0000] {subprocess.py:93} INFO - Dependents                               float64
[2025-08-19T17:52:12.034+0000] {subprocess.py:93} INFO - tenure                                   float64
[2025-08-19T17:52:12.035+0000] {subprocess.py:93} INFO - PhoneService                             float64
[2025-08-19T17:52:12.037+0000] {subprocess.py:93} INFO - PaperlessBilling                         float64
[2025-08-19T17:52:12.038+0000] {subprocess.py:93} INFO - MonthlyCharges                           float64
[2025-08-19T17:52:12.039+0000] {subprocess.py:93} INFO - TotalCharges                             float64
[2025-08-19T17:52:12.040+0000] {subprocess.py:93} INFO - TotalChargesPerTenure                    float64
[2025-08-19T17:52:12.042+0000] {subprocess.py:93} INFO - MultipleLines_No phone service           float64
[2025-08-19T17:52:12.044+0000] {subprocess.py:93} INFO - MultipleLines_Yes                        float64
[2025-08-19T17:52:12.045+0000] {subprocess.py:93} INFO - InternetService_Fiber optic              float64
[2025-08-19T17:52:12.046+0000] {subprocess.py:93} INFO - InternetService_No                       float64
[2025-08-19T17:52:12.047+0000] {subprocess.py:93} INFO - OnlineSecurity_No internet service       float64
[2025-08-19T17:52:12.048+0000] {subprocess.py:93} INFO - OnlineSecurity_Yes                       float64
[2025-08-19T17:52:12.049+0000] {subprocess.py:93} INFO - OnlineBackup_No internet service         float64
[2025-08-19T17:52:12.050+0000] {subprocess.py:93} INFO - OnlineBackup_Yes                         float64
[2025-08-19T17:52:12.051+0000] {subprocess.py:93} INFO - DeviceProtection_No internet service     float64
[2025-08-19T17:52:12.052+0000] {subprocess.py:93} INFO - DeviceProtection_Yes                     float64
[2025-08-19T17:52:12.053+0000] {subprocess.py:93} INFO - TechSupport_No internet service          float64
[2025-08-19T17:52:12.055+0000] {subprocess.py:93} INFO - TechSupport_Yes                          float64
[2025-08-19T17:52:12.056+0000] {subprocess.py:93} INFO - StreamingTV_No internet service          float64
[2025-08-19T17:52:12.057+0000] {subprocess.py:93} INFO - StreamingTV_Yes                          float64
[2025-08-19T17:52:12.057+0000] {subprocess.py:93} INFO - StreamingMovies_No internet service      float64
[2025-08-19T17:52:12.058+0000] {subprocess.py:93} INFO - StreamingMovies_Yes                      float64
[2025-08-19T17:52:12.061+0000] {subprocess.py:93} INFO - Contract_One year                        float64
[2025-08-19T17:52:12.062+0000] {subprocess.py:93} INFO - Contract_Two year                        float64
[2025-08-19T17:52:12.063+0000] {subprocess.py:93} INFO - PaymentMethod_Credit card (automatic)    float64
[2025-08-19T17:52:12.064+0000] {subprocess.py:93} INFO - PaymentMethod_Electronic check           float64
[2025-08-19T17:52:12.064+0000] {subprocess.py:93} INFO - PaymentMethod_Mailed check               float64
[2025-08-19T17:52:12.065+0000] {subprocess.py:93} INFO - TenureGroup_13-24                        float64
[2025-08-19T17:52:12.067+0000] {subprocess.py:93} INFO - TenureGroup_25-48                        float64
[2025-08-19T17:52:12.068+0000] {subprocess.py:93} INFO - TenureGroup_49-60                        float64
[2025-08-19T17:52:12.068+0000] {subprocess.py:93} INFO - TenureGroup_61+                          float64
[2025-08-19T17:52:12.069+0000] {subprocess.py:93} INFO - dtype: object
[2025-08-19T17:52:12.070+0000] {subprocess.py:93} INFO - 2025-08-19 17:52:12,029 INFO Unique classes in target: [0 1]
[2025-08-19T17:52:12.075+0000] {subprocess.py:93} INFO - 2025-08-19 17:52:12,030 INFO Class distribution: [5163 1869]
[2025-08-19T17:52:14.375+0000] {subprocess.py:93} INFO - 2025-08-19 17:52:14,375 INFO Logistic Regression recall=0.7807, acc=0.7306, prec=0.4958, f1=0.6064
[2025-08-19T17:52:14.393+0000] {subprocess.py:93} INFO - 2025-08-19 17:52:14,393 INFO Classification report:
[2025-08-19T17:52:14.394+0000] {subprocess.py:93} INFO -               precision    recall  f1-score   support
[2025-08-19T17:52:14.395+0000] {subprocess.py:93} INFO - 
[2025-08-19T17:52:14.396+0000] {subprocess.py:93} INFO -            0       0.90      0.71      0.80      1033
[2025-08-19T17:52:14.397+0000] {subprocess.py:93} INFO -            1       0.50      0.78      0.61       374
[2025-08-19T17:52:14.409+0000] {subprocess.py:93} INFO - 
[2025-08-19T17:52:14.410+0000] {subprocess.py:93} INFO -     accuracy                           0.73      1407
[2025-08-19T17:52:14.411+0000] {subprocess.py:93} INFO -    macro avg       0.70      0.75      0.70      1407
[2025-08-19T17:52:14.411+0000] {subprocess.py:93} INFO - weighted avg       0.79      0.73      0.75      1407
[2025-08-19T17:52:14.412+0000] {subprocess.py:93} INFO - 
[2025-08-19T17:52:16.702+0000] {subprocess.py:93} INFO - 2025-08-19 17:52:16,702 INFO RandomForest recall=0.4733, acc=0.7953, prec=0.6604, f1=0.5514
[2025-08-19T17:52:16.716+0000] {subprocess.py:93} INFO - 2025-08-19 17:52:16,716 INFO Classification report:
[2025-08-19T17:52:16.717+0000] {subprocess.py:93} INFO -               precision    recall  f1-score   support
[2025-08-19T17:52:16.718+0000] {subprocess.py:93} INFO - 
[2025-08-19T17:52:16.719+0000] {subprocess.py:93} INFO -            0       0.83      0.91      0.87      1033
[2025-08-19T17:52:16.720+0000] {subprocess.py:93} INFO -            1       0.66      0.47      0.55       374
[2025-08-19T17:52:16.721+0000] {subprocess.py:93} INFO - 
[2025-08-19T17:52:16.722+0000] {subprocess.py:93} INFO -     accuracy                           0.80      1407
[2025-08-19T17:52:16.723+0000] {subprocess.py:93} INFO -    macro avg       0.74      0.69      0.71      1407
[2025-08-19T17:52:16.725+0000] {subprocess.py:93} INFO - weighted avg       0.78      0.80      0.78      1407
[2025-08-19T17:52:16.726+0000] {subprocess.py:93} INFO - 
[2025-08-19T17:52:16.815+0000] {subprocess.py:93} INFO - 2025-08-19 17:52:16,814 INFO Best model (LogisticRegression) saved locally to models/churn_model.pkl with recall=0.7807
[2025-08-19T17:52:16.816+0000] {subprocess.py:93} INFO - 2025-08-19 17:52:16,815 INFO Best run_id written to /tmp/best_run_id.txt
[2025-08-19T17:52:25.731+0000] {subprocess.py:93} INFO - /home/***/.local/lib/python3.8/site-packages/mlflow/types/utils.py:407: UserWarning: Hint: Inferred schema contains integer column(s). Integer columns in Python cannot represent missing values. If your input data contains missing values at inference time, it will be encoded as floats and will cause a schema enforcement error. The best way to avoid this problem is to infer the model schema based on a realistic data sample (training dataset) that includes missing values. Alternatively, you can declare integer columns as doubles (float64) whenever these columns may have missing values. See `Handling Integers With Missing Values <https://www.mlflow.org/docs/latest/models.html#handling-integers-with-missing-values>`_ for more details.
[2025-08-19T17:52:25.732+0000] {subprocess.py:93} INFO -   warnings.warn(
[2025-08-19T17:52:25.734+0000] {subprocess.py:93} INFO - Registered model 'churn_model' already exists. Creating a new version of this model...
[2025-08-19T17:52:25.735+0000] {subprocess.py:93} INFO - 2025-08-19 17:52:25,731 WARNING Model Version creation error (name=churn_model) Retrying 2 more times.
[2025-08-19T17:52:25.927+0000] {subprocess.py:93} INFO - 2025-08-19 17:52:25,926 WARNING Model Version creation error (name=churn_model) Retrying 1 more time.
[2025-08-19T17:52:26.123+0000] {subprocess.py:93} INFO - 2025-08-19 17:52:26,122 WARNING Model Version creation error (name=churn_model) Retrying 0 more time.
[2025-08-19T17:52:26.208+0000] {subprocess.py:93} INFO - 2025-08-19 17:52:26,207 WARNING MLflow model registry logging failed: Model Version creation error (name=churn_model). Error: [Errno 1] Operation not permitted. Giving up after 3 attempts.. Continuing with local model only.
[2025-08-19T17:52:26.795+0000] {subprocess.py:97} INFO - Command exited with return code 0
[2025-08-19T17:52:26.852+0000] {taskinstance.py:1149} INFO - Marking task as SUCCESS. dag_id=customer_churn_pipeline, task_id=model_training, execution_date=20250819T175123, start_date=20250819T175206, end_date=20250819T175226
[2025-08-19T17:52:26.905+0000] {local_task_job_runner.py:234} INFO - Task exited with return code 0
[2025-08-19T17:52:26.944+0000] {taskinstance.py:3312} INFO - 1 downstream tasks scheduled from follow-on schedule check
