[2025-08-18T20:01:40.783+0000] {taskinstance.py:1979} INFO - Dependencies all met for dep_context=non-requeueable deps ti=<TaskInstance: customer_churn_pipeline.data_preparation manual__2025-08-18T20:01:25.338641+00:00 [queued]>
[2025-08-18T20:01:40.797+0000] {taskinstance.py:1979} INFO - Dependencies all met for dep_context=requeueable deps ti=<TaskInstance: customer_churn_pipeline.data_preparation manual__2025-08-18T20:01:25.338641+00:00 [queued]>
[2025-08-18T20:01:40.799+0000] {taskinstance.py:2193} INFO - Starting attempt 1 of 1
[2025-08-18T20:01:40.817+0000] {taskinstance.py:2217} INFO - Executing <Task(BashOperator): data_preparation> on 2025-08-18 20:01:25.338641+00:00
[2025-08-18T20:01:40.824+0000] {standard_task_runner.py:60} INFO - Started process 340 to run task
[2025-08-18T20:01:40.828+0000] {standard_task_runner.py:87} INFO - Running: ['***', 'tasks', 'run', 'customer_churn_pipeline', 'data_preparation', 'manual__2025-08-18T20:01:25.338641+00:00', '--job-id', '23', '--raw', '--subdir', 'DAGS_FOLDER/customer_churn_pipeline_dag.py', '--cfg-path', '/tmp/tmpi84erfc3']
[2025-08-18T20:01:40.832+0000] {standard_task_runner.py:88} INFO - Job 23: Subtask data_preparation
[2025-08-18T20:01:40.900+0000] {task_command.py:423} INFO - Running <TaskInstance: customer_churn_pipeline.data_preparation manual__2025-08-18T20:01:25.338641+00:00 [running]> on host 2edf98569333
[2025-08-18T20:01:40.986+0000] {taskinstance.py:2513} INFO - Exporting env vars: AIRFLOW_CTX_DAG_OWNER='***' AIRFLOW_CTX_DAG_ID='customer_churn_pipeline' AIRFLOW_CTX_TASK_ID='data_preparation' AIRFLOW_CTX_EXECUTION_DATE='2025-08-18T20:01:25.338641+00:00' AIRFLOW_CTX_TRY_NUMBER='1' AIRFLOW_CTX_DAG_RUN_ID='manual__2025-08-18T20:01:25.338641+00:00'
[2025-08-18T20:01:40.989+0000] {subprocess.py:63} INFO - Tmp dir root location: /tmp
[2025-08-18T20:01:40.991+0000] {subprocess.py:75} INFO - Running command: ['/usr/bin/bash', '-c', 'cd /opt/***/Customer_Churn_Prediction_Pipeline && python src/preparation.py']
[2025-08-18T20:01:41.006+0000] {subprocess.py:86} INFO - Output:
[2025-08-18T20:01:42.681+0000] {subprocess.py:93} INFO - Traceback (most recent call last):
[2025-08-18T20:01:42.682+0000] {subprocess.py:93} INFO -   File "src/preparation.py", line 5, in <module>
[2025-08-18T20:01:42.683+0000] {subprocess.py:93} INFO -     import seaborn as sns
[2025-08-18T20:01:42.683+0000] {subprocess.py:93} INFO - ModuleNotFoundError: No module named 'seaborn'
[2025-08-18T20:01:42.834+0000] {subprocess.py:97} INFO - Command exited with return code 1
[2025-08-18T20:01:42.852+0000] {taskinstance.py:2731} ERROR - Task failed with exception
Traceback (most recent call last):
  File "/home/airflow/.local/lib/python3.8/site-packages/airflow/models/taskinstance.py", line 444, in _execute_task
    result = _execute_callable(context=context, **execute_callable_kwargs)
  File "/home/airflow/.local/lib/python3.8/site-packages/airflow/models/taskinstance.py", line 414, in _execute_callable
    return execute_callable(context=context, **execute_callable_kwargs)
  File "/home/airflow/.local/lib/python3.8/site-packages/airflow/operators/bash.py", line 212, in execute
    raise AirflowException(
airflow.exceptions.AirflowException: Bash command failed. The command returned a non-zero exit code 1.
[2025-08-18T20:01:42.857+0000] {taskinstance.py:1149} INFO - Marking task as FAILED. dag_id=customer_churn_pipeline, task_id=data_preparation, execution_date=20250818T200125, start_date=20250818T200140, end_date=20250818T200142
[2025-08-18T20:01:42.873+0000] {standard_task_runner.py:107} ERROR - Failed to execute job 23 for task data_preparation (Bash command failed. The command returned a non-zero exit code 1.; 340)
[2025-08-18T20:01:42.911+0000] {local_task_job_runner.py:234} INFO - Task exited with return code 1
[2025-08-18T20:01:42.943+0000] {taskinstance.py:3312} INFO - 0 downstream tasks scheduled from follow-on schedule check
