[2025-08-18T20:10:48.234+0000] {taskinstance.py:1979} INFO - Dependencies all met for dep_context=non-requeueable deps ti=<TaskInstance: customer_churn_pipeline.model_training manual__2025-08-18T20:10:17.353248+00:00 [queued]>
[2025-08-18T20:10:48.247+0000] {taskinstance.py:1979} INFO - Dependencies all met for dep_context=requeueable deps ti=<TaskInstance: customer_churn_pipeline.model_training manual__2025-08-18T20:10:17.353248+00:00 [queued]>
[2025-08-18T20:10:48.248+0000] {taskinstance.py:2193} INFO - Starting attempt 1 of 1
[2025-08-18T20:10:48.266+0000] {taskinstance.py:2217} INFO - Executing <Task(BashOperator): model_training> on 2025-08-18 20:10:17.353248+00:00
[2025-08-18T20:10:48.271+0000] {standard_task_runner.py:60} INFO - Started process 353 to run task
[2025-08-18T20:10:48.275+0000] {standard_task_runner.py:87} INFO - Running: ['***', 'tasks', 'run', 'customer_churn_pipeline', 'model_training', 'manual__2025-08-18T20:10:17.353248+00:00', '--job-id', '30', '--raw', '--subdir', 'DAGS_FOLDER/customer_churn_pipeline_dag.py', '--cfg-path', '/tmp/tmpjcmn3fo8']
[2025-08-18T20:10:48.279+0000] {standard_task_runner.py:88} INFO - Job 30: Subtask model_training
[2025-08-18T20:10:48.343+0000] {task_command.py:423} INFO - Running <TaskInstance: customer_churn_pipeline.model_training manual__2025-08-18T20:10:17.353248+00:00 [running]> on host 6cfe0da8a177
[2025-08-18T20:10:48.428+0000] {taskinstance.py:2513} INFO - Exporting env vars: AIRFLOW_CTX_DAG_OWNER='***' AIRFLOW_CTX_DAG_ID='customer_churn_pipeline' AIRFLOW_CTX_TASK_ID='model_training' AIRFLOW_CTX_EXECUTION_DATE='2025-08-18T20:10:17.353248+00:00' AIRFLOW_CTX_TRY_NUMBER='1' AIRFLOW_CTX_DAG_RUN_ID='manual__2025-08-18T20:10:17.353248+00:00'
[2025-08-18T20:10:48.431+0000] {subprocess.py:63} INFO - Tmp dir root location: /tmp
[2025-08-18T20:10:48.432+0000] {subprocess.py:75} INFO - Running command: ['/usr/bin/bash', '-c', 'cd /opt/***/Customer_Churn_Prediction_Pipeline && python src/train_model.py']
[2025-08-18T20:10:48.444+0000] {subprocess.py:86} INFO - Output:
[2025-08-18T20:10:50.659+0000] {subprocess.py:93} INFO - 2025-08-18 20:10:50,659 INFO Loading features and target from feature store...
[2025-08-18T20:10:50.660+0000] {subprocess.py:93} INFO - 2025-08-18 20:10:50,659 INFO Connecting to SQLite DB at data/features/churn_features.db
[2025-08-18T20:10:50.673+0000] {subprocess.py:93} INFO - 2025-08-18 20:10:50,673 INFO Available tables: ['churn_features']
[2025-08-18T20:10:50.927+0000] {subprocess.py:93} INFO - 2025-08-18 20:10:50,926 INFO Retrieved 7032 rows and 36 columns from table churn_features
[2025-08-18T20:10:50.930+0000] {subprocess.py:93} INFO - 2025-08-18 20:10:50,930 INFO Features shape: (7032, 35), Target shape: (7032,)
[2025-08-18T20:10:50.931+0000] {subprocess.py:93} INFO - 2025-08-18 20:10:50,930 INFO Loaded features shape: (7032, 35), target shape: (7032,)
[2025-08-18T20:10:50.932+0000] {subprocess.py:93} INFO - 2025-08-18 20:10:50,930 INFO Splitting data into train and test sets (80/20, stratified)...
[2025-08-18T20:10:52.356+0000] {subprocess.py:93} INFO - 2025-08-18 20:10:52,356 INFO Training Logistic Regression...
[2025-08-18T20:10:54.385+0000] {subprocess.py:93} INFO - 2025-08-18 20:10:54,385 INFO Logistic Regression recall: 0.5187, accuracy: 0.7946, precision: 0.6403, f1: 0.5731
[2025-08-18T20:10:54.399+0000] {subprocess.py:93} INFO - 2025-08-18 20:10:54,399 INFO Classification report:
[2025-08-18T20:10:54.401+0000] {subprocess.py:93} INFO -               precision    recall  f1-score   support
[2025-08-18T20:10:54.402+0000] {subprocess.py:93} INFO - 
[2025-08-18T20:10:54.403+0000] {subprocess.py:93} INFO -            0       0.84      0.89      0.86      1033
[2025-08-18T20:10:54.404+0000] {subprocess.py:93} INFO -            1       0.64      0.52      0.57       374
[2025-08-18T20:10:54.405+0000] {subprocess.py:93} INFO - 
[2025-08-18T20:10:54.408+0000] {subprocess.py:93} INFO -     accuracy                           0.79      1407
[2025-08-18T20:10:54.409+0000] {subprocess.py:93} INFO -    macro avg       0.74      0.71      0.72      1407
[2025-08-18T20:10:54.419+0000] {subprocess.py:93} INFO - weighted avg       0.78      0.79      0.79      1407
[2025-08-18T20:10:54.420+0000] {subprocess.py:93} INFO - 
[2025-08-18T20:10:55.422+0000] {subprocess.py:93} INFO - 2025-08-18 20:10:55,422 INFO Training Random Forest Classifier...
[2025-08-18T20:10:56.630+0000] {subprocess.py:93} INFO - 2025-08-18 20:10:56,629 INFO Random Forest recall: 0.4706, accuracy: 0.7910, precision: 0.6471, f1: 0.5449
[2025-08-18T20:10:56.642+0000] {subprocess.py:93} INFO - 2025-08-18 20:10:56,641 INFO Classification report:
[2025-08-18T20:10:56.643+0000] {subprocess.py:93} INFO -               precision    recall  f1-score   support
[2025-08-18T20:10:56.644+0000] {subprocess.py:93} INFO - 
[2025-08-18T20:10:56.645+0000] {subprocess.py:93} INFO -            0       0.83      0.91      0.86      1033
[2025-08-18T20:10:56.646+0000] {subprocess.py:93} INFO -            1       0.65      0.47      0.54       374
[2025-08-18T20:10:56.646+0000] {subprocess.py:93} INFO - 
[2025-08-18T20:10:56.650+0000] {subprocess.py:93} INFO -     accuracy                           0.79      1407
[2025-08-18T20:10:56.651+0000] {subprocess.py:93} INFO -    macro avg       0.74      0.69      0.70      1407
[2025-08-18T20:10:56.652+0000] {subprocess.py:93} INFO - weighted avg       0.78      0.79      0.78      1407
[2025-08-18T20:10:56.653+0000] {subprocess.py:93} INFO - 
[2025-08-18T20:10:56.730+0000] {subprocess.py:93} INFO - 2025-08-18 20:10:56,730 INFO Best model (LogisticRegression) saved to models/churn_model.pkl with recall 0.5187
[2025-08-18T20:10:56.744+0000] {subprocess.py:93} INFO - Traceback (most recent call last):
[2025-08-18T20:10:56.746+0000] {subprocess.py:93} INFO -   File "src/train_model.py", line 91, in <module>
[2025-08-18T20:10:56.746+0000] {subprocess.py:93} INFO -     mlflow.sklearn.log_model(best_model, name='model', input_example=input_example)
[2025-08-18T20:10:56.747+0000] {subprocess.py:93} INFO - TypeError: log_model() got an unexpected keyword argument 'name'
[2025-08-18T20:10:57.077+0000] {subprocess.py:97} INFO - Command exited with return code 1
[2025-08-18T20:10:57.091+0000] {taskinstance.py:2731} ERROR - Task failed with exception
Traceback (most recent call last):
  File "/home/airflow/.local/lib/python3.8/site-packages/airflow/models/taskinstance.py", line 444, in _execute_task
    result = _execute_callable(context=context, **execute_callable_kwargs)
  File "/home/airflow/.local/lib/python3.8/site-packages/airflow/models/taskinstance.py", line 414, in _execute_callable
    return execute_callable(context=context, **execute_callable_kwargs)
  File "/home/airflow/.local/lib/python3.8/site-packages/airflow/operators/bash.py", line 212, in execute
    raise AirflowException(
airflow.exceptions.AirflowException: Bash command failed. The command returned a non-zero exit code 1.
[2025-08-18T20:10:57.095+0000] {taskinstance.py:1149} INFO - Marking task as FAILED. dag_id=customer_churn_pipeline, task_id=model_training, execution_date=20250818T201017, start_date=20250818T201048, end_date=20250818T201057
[2025-08-18T20:10:57.113+0000] {standard_task_runner.py:107} ERROR - Failed to execute job 30 for task model_training (Bash command failed. The command returned a non-zero exit code 1.; 353)
[2025-08-18T20:10:57.148+0000] {local_task_job_runner.py:234} INFO - Task exited with return code 1
[2025-08-18T20:10:57.171+0000] {taskinstance.py:3312} INFO - 0 downstream tasks scheduled from follow-on schedule check
