[2025-08-20T17:49:21.051+0000] {taskinstance.py:1979} INFO - Dependencies all met for dep_context=non-requeueable deps ti=<TaskInstance: customer_churn_pipeline.model_training scheduled__2025-08-19T00:00:00+00:00 [queued]>
[2025-08-20T17:49:21.084+0000] {taskinstance.py:1979} INFO - Dependencies all met for dep_context=requeueable deps ti=<TaskInstance: customer_churn_pipeline.model_training scheduled__2025-08-19T00:00:00+00:00 [queued]>
[2025-08-20T17:49:21.085+0000] {taskinstance.py:2193} INFO - Starting attempt 1 of 1
[2025-08-20T17:49:21.159+0000] {taskinstance.py:2217} INFO - Executing <Task(BashOperator): model_training> on 2025-08-19 00:00:00+00:00
[2025-08-20T17:49:21.182+0000] {standard_task_runner.py:60} INFO - Started process 353 to run task
[2025-08-20T17:49:21.214+0000] {standard_task_runner.py:87} INFO - Running: ['***', 'tasks', 'run', 'customer_churn_pipeline', 'model_training', 'scheduled__2025-08-19T00:00:00+00:00', '--job-id', '12', '--raw', '--subdir', 'DAGS_FOLDER/customer_churn_pipeline_dag.py', '--cfg-path', '/tmp/tmpol5_x3a8']
[2025-08-20T17:49:21.223+0000] {standard_task_runner.py:88} INFO - Job 12: Subtask model_training
[2025-08-20T17:49:21.492+0000] {task_command.py:423} INFO - Running <TaskInstance: customer_churn_pipeline.model_training scheduled__2025-08-19T00:00:00+00:00 [running]> on host bd9202be787f
[2025-08-20T17:49:21.875+0000] {taskinstance.py:2513} INFO - Exporting env vars: AIRFLOW_CTX_DAG_OWNER='***' AIRFLOW_CTX_DAG_ID='customer_churn_pipeline' AIRFLOW_CTX_TASK_ID='model_training' AIRFLOW_CTX_EXECUTION_DATE='2025-08-19T00:00:00+00:00' AIRFLOW_CTX_TRY_NUMBER='1' AIRFLOW_CTX_DAG_RUN_ID='scheduled__2025-08-19T00:00:00+00:00'
[2025-08-20T17:49:21.880+0000] {subprocess.py:63} INFO - Tmp dir root location: /tmp
[2025-08-20T17:49:21.883+0000] {subprocess.py:75} INFO - Running command: ['/usr/bin/bash', '-c', 'cd /opt/***/Customer_Churn_Prediction_Pipeline && python src/train_model.py']
[2025-08-20T17:49:21.915+0000] {subprocess.py:86} INFO - Output:
[2025-08-20T17:49:44.309+0000] {subprocess.py:93} INFO - 2025-08-20 17:49:44,260 WARNING Malformed experiment '3c451db2cddf461b9fa24b573ecdc116'. Detailed error Yaml file '/opt/***/Customer_Churn_Prediction_Pipeline/mlruns/3c451db2cddf461b9fa24b573ecdc116/meta.yaml' does not exist.
[2025-08-20T17:49:44.323+0000] {subprocess.py:93} INFO - Traceback (most recent call last):
[2025-08-20T17:49:44.328+0000] {subprocess.py:93} INFO -   File "/home/***/.local/lib/python3.8/site-packages/mlflow/store/tracking/file_store.py", line 327, in search_experiments
[2025-08-20T17:49:44.331+0000] {subprocess.py:93} INFO -     exp = self._get_experiment(exp_id, view_type)
[2025-08-20T17:49:44.339+0000] {subprocess.py:93} INFO -   File "/home/***/.local/lib/python3.8/site-packages/mlflow/store/tracking/file_store.py", line 421, in _get_experiment
[2025-08-20T17:49:44.342+0000] {subprocess.py:93} INFO -     meta = FileStore._read_yaml(experiment_dir, FileStore.META_DATA_FILE_NAME)
[2025-08-20T17:49:44.361+0000] {subprocess.py:93} INFO -   File "/home/***/.local/lib/python3.8/site-packages/mlflow/store/tracking/file_store.py", line 1367, in _read_yaml
[2025-08-20T17:49:44.364+0000] {subprocess.py:93} INFO -     return _read_helper(root, file_name, attempts_remaining=retries)
[2025-08-20T17:49:44.365+0000] {subprocess.py:93} INFO -   File "/home/***/.local/lib/python3.8/site-packages/mlflow/store/tracking/file_store.py", line 1360, in _read_helper
[2025-08-20T17:49:44.374+0000] {subprocess.py:93} INFO -     result = read_yaml(root, file_name)
[2025-08-20T17:49:44.376+0000] {subprocess.py:93} INFO -   File "/home/***/.local/lib/python3.8/site-packages/mlflow/utils/file_utils.py", line 309, in read_yaml
[2025-08-20T17:49:44.400+0000] {subprocess.py:93} INFO -     raise MissingConfigException(f"Yaml file '{file_path}' does not exist.")
[2025-08-20T17:49:44.412+0000] {subprocess.py:93} INFO - mlflow.exceptions.MissingConfigException: Yaml file '/opt/***/Customer_Churn_Prediction_Pipeline/mlruns/3c451db2cddf461b9fa24b573ecdc116/meta.yaml' does not exist.
[2025-08-20T17:49:45.074+0000] {subprocess.py:93} INFO - 2025-08-20 17:49:45,073 WARNING Malformed experiment '66a6a96d2c6e463cbcf97c942dce679d'. Detailed error Yaml file '/opt/***/Customer_Churn_Prediction_Pipeline/mlruns/66a6a96d2c6e463cbcf97c942dce679d/meta.yaml' does not exist.
[2025-08-20T17:49:45.087+0000] {subprocess.py:93} INFO - Traceback (most recent call last):
[2025-08-20T17:49:45.088+0000] {subprocess.py:93} INFO -   File "/home/***/.local/lib/python3.8/site-packages/mlflow/store/tracking/file_store.py", line 327, in search_experiments
[2025-08-20T17:49:45.090+0000] {subprocess.py:93} INFO -     exp = self._get_experiment(exp_id, view_type)
[2025-08-20T17:49:45.091+0000] {subprocess.py:93} INFO -   File "/home/***/.local/lib/python3.8/site-packages/mlflow/store/tracking/file_store.py", line 421, in _get_experiment
[2025-08-20T17:49:45.092+0000] {subprocess.py:93} INFO -     meta = FileStore._read_yaml(experiment_dir, FileStore.META_DATA_FILE_NAME)
[2025-08-20T17:49:45.093+0000] {subprocess.py:93} INFO -   File "/home/***/.local/lib/python3.8/site-packages/mlflow/store/tracking/file_store.py", line 1367, in _read_yaml
[2025-08-20T17:49:45.095+0000] {subprocess.py:93} INFO -     return _read_helper(root, file_name, attempts_remaining=retries)
[2025-08-20T17:49:45.101+0000] {subprocess.py:93} INFO -   File "/home/***/.local/lib/python3.8/site-packages/mlflow/store/tracking/file_store.py", line 1360, in _read_helper
[2025-08-20T17:49:45.104+0000] {subprocess.py:93} INFO -     result = read_yaml(root, file_name)
[2025-08-20T17:49:45.108+0000] {subprocess.py:93} INFO -   File "/home/***/.local/lib/python3.8/site-packages/mlflow/utils/file_utils.py", line 309, in read_yaml
[2025-08-20T17:49:45.110+0000] {subprocess.py:93} INFO -     raise MissingConfigException(f"Yaml file '{file_path}' does not exist.")
[2025-08-20T17:49:45.112+0000] {subprocess.py:93} INFO - mlflow.exceptions.MissingConfigException: Yaml file '/opt/***/Customer_Churn_Prediction_Pipeline/mlruns/66a6a96d2c6e463cbcf97c942dce679d/meta.yaml' does not exist.
[2025-08-20T17:49:45.114+0000] {subprocess.py:93} INFO - 2025-08-20 17:49:45,113 WARNING Malformed experiment '758f77ef4c794795bdfdff4c02503bcc'. Detailed error Yaml file '/opt/***/Customer_Churn_Prediction_Pipeline/mlruns/758f77ef4c794795bdfdff4c02503bcc/meta.yaml' does not exist.
[2025-08-20T17:49:45.121+0000] {subprocess.py:93} INFO - Traceback (most recent call last):
[2025-08-20T17:49:45.125+0000] {subprocess.py:93} INFO -   File "/home/***/.local/lib/python3.8/site-packages/mlflow/store/tracking/file_store.py", line 327, in search_experiments
[2025-08-20T17:49:45.126+0000] {subprocess.py:93} INFO -     exp = self._get_experiment(exp_id, view_type)
[2025-08-20T17:49:45.127+0000] {subprocess.py:93} INFO -   File "/home/***/.local/lib/python3.8/site-packages/mlflow/store/tracking/file_store.py", line 421, in _get_experiment
[2025-08-20T17:49:45.129+0000] {subprocess.py:93} INFO -     meta = FileStore._read_yaml(experiment_dir, FileStore.META_DATA_FILE_NAME)
[2025-08-20T17:49:45.130+0000] {subprocess.py:93} INFO -   File "/home/***/.local/lib/python3.8/site-packages/mlflow/store/tracking/file_store.py", line 1367, in _read_yaml
[2025-08-20T17:49:45.131+0000] {subprocess.py:93} INFO -     return _read_helper(root, file_name, attempts_remaining=retries)
[2025-08-20T17:49:45.133+0000] {subprocess.py:93} INFO -   File "/home/***/.local/lib/python3.8/site-packages/mlflow/store/tracking/file_store.py", line 1360, in _read_helper
[2025-08-20T17:49:45.137+0000] {subprocess.py:93} INFO -     result = read_yaml(root, file_name)
[2025-08-20T17:49:45.138+0000] {subprocess.py:93} INFO -   File "/home/***/.local/lib/python3.8/site-packages/mlflow/utils/file_utils.py", line 309, in read_yaml
[2025-08-20T17:49:45.147+0000] {subprocess.py:93} INFO -     raise MissingConfigException(f"Yaml file '{file_path}' does not exist.")
[2025-08-20T17:49:45.148+0000] {subprocess.py:93} INFO - mlflow.exceptions.MissingConfigException: Yaml file '/opt/***/Customer_Churn_Prediction_Pipeline/mlruns/758f77ef4c794795bdfdff4c02503bcc/meta.yaml' does not exist.
[2025-08-20T17:49:45.159+0000] {subprocess.py:93} INFO - 2025-08-20 17:49:45,159 WARNING Malformed experiment '7a4c300b24d14505ba7f4df32748abf9'. Detailed error Yaml file '/opt/***/Customer_Churn_Prediction_Pipeline/mlruns/7a4c300b24d14505ba7f4df32748abf9/meta.yaml' does not exist.
[2025-08-20T17:49:45.161+0000] {subprocess.py:93} INFO - Traceback (most recent call last):
[2025-08-20T17:49:45.162+0000] {subprocess.py:93} INFO -   File "/home/***/.local/lib/python3.8/site-packages/mlflow/store/tracking/file_store.py", line 327, in search_experiments
[2025-08-20T17:49:45.163+0000] {subprocess.py:93} INFO -     exp = self._get_experiment(exp_id, view_type)
[2025-08-20T17:49:45.165+0000] {subprocess.py:93} INFO -   File "/home/***/.local/lib/python3.8/site-packages/mlflow/store/tracking/file_store.py", line 421, in _get_experiment
[2025-08-20T17:49:45.167+0000] {subprocess.py:93} INFO -     meta = FileStore._read_yaml(experiment_dir, FileStore.META_DATA_FILE_NAME)
[2025-08-20T17:49:45.168+0000] {subprocess.py:93} INFO -   File "/home/***/.local/lib/python3.8/site-packages/mlflow/store/tracking/file_store.py", line 1367, in _read_yaml
[2025-08-20T17:49:45.175+0000] {subprocess.py:93} INFO -     return _read_helper(root, file_name, attempts_remaining=retries)
[2025-08-20T17:49:45.178+0000] {subprocess.py:93} INFO -   File "/home/***/.local/lib/python3.8/site-packages/mlflow/store/tracking/file_store.py", line 1360, in _read_helper
[2025-08-20T17:49:45.181+0000] {subprocess.py:93} INFO -     result = read_yaml(root, file_name)
[2025-08-20T17:49:45.193+0000] {subprocess.py:93} INFO -   File "/home/***/.local/lib/python3.8/site-packages/mlflow/utils/file_utils.py", line 309, in read_yaml
[2025-08-20T17:49:45.197+0000] {subprocess.py:93} INFO -     raise MissingConfigException(f"Yaml file '{file_path}' does not exist.")
[2025-08-20T17:49:45.198+0000] {subprocess.py:93} INFO - mlflow.exceptions.MissingConfigException: Yaml file '/opt/***/Customer_Churn_Prediction_Pipeline/mlruns/7a4c300b24d14505ba7f4df32748abf9/meta.yaml' does not exist.
[2025-08-20T17:49:45.211+0000] {subprocess.py:93} INFO - 2025-08-20 17:49:45,207 WARNING Malformed experiment '7fd6ebbc25ba485ba1086b06b2552e0e'. Detailed error Yaml file '/opt/***/Customer_Churn_Prediction_Pipeline/mlruns/7fd6ebbc25ba485ba1086b06b2552e0e/meta.yaml' does not exist.
[2025-08-20T17:49:45.215+0000] {subprocess.py:93} INFO - Traceback (most recent call last):
[2025-08-20T17:49:45.220+0000] {subprocess.py:93} INFO -   File "/home/***/.local/lib/python3.8/site-packages/mlflow/store/tracking/file_store.py", line 327, in search_experiments
[2025-08-20T17:49:45.233+0000] {subprocess.py:93} INFO -     exp = self._get_experiment(exp_id, view_type)
[2025-08-20T17:49:45.234+0000] {subprocess.py:93} INFO -   File "/home/***/.local/lib/python3.8/site-packages/mlflow/store/tracking/file_store.py", line 421, in _get_experiment
[2025-08-20T17:49:45.236+0000] {subprocess.py:93} INFO -     meta = FileStore._read_yaml(experiment_dir, FileStore.META_DATA_FILE_NAME)
[2025-08-20T17:49:45.237+0000] {subprocess.py:93} INFO -   File "/home/***/.local/lib/python3.8/site-packages/mlflow/store/tracking/file_store.py", line 1367, in _read_yaml
[2025-08-20T17:49:45.238+0000] {subprocess.py:93} INFO -     return _read_helper(root, file_name, attempts_remaining=retries)
[2025-08-20T17:49:45.239+0000] {subprocess.py:93} INFO -   File "/home/***/.local/lib/python3.8/site-packages/mlflow/store/tracking/file_store.py", line 1360, in _read_helper
[2025-08-20T17:49:45.241+0000] {subprocess.py:93} INFO -     result = read_yaml(root, file_name)
[2025-08-20T17:49:45.242+0000] {subprocess.py:93} INFO -   File "/home/***/.local/lib/python3.8/site-packages/mlflow/utils/file_utils.py", line 309, in read_yaml
[2025-08-20T17:49:45.253+0000] {subprocess.py:93} INFO -     raise MissingConfigException(f"Yaml file '{file_path}' does not exist.")
[2025-08-20T17:49:45.256+0000] {subprocess.py:93} INFO - mlflow.exceptions.MissingConfigException: Yaml file '/opt/***/Customer_Churn_Prediction_Pipeline/mlruns/7fd6ebbc25ba485ba1086b06b2552e0e/meta.yaml' does not exist.
[2025-08-20T17:49:45.271+0000] {subprocess.py:93} INFO - 2025-08-20 17:49:45,270 WARNING Malformed experiment '9f8a2292aea24d39a6b035889d38fb72'. Detailed error Yaml file '/opt/***/Customer_Churn_Prediction_Pipeline/mlruns/9f8a2292aea24d39a6b035889d38fb72/meta.yaml' does not exist.
[2025-08-20T17:49:45.275+0000] {subprocess.py:93} INFO - Traceback (most recent call last):
[2025-08-20T17:49:45.285+0000] {subprocess.py:93} INFO -   File "/home/***/.local/lib/python3.8/site-packages/mlflow/store/tracking/file_store.py", line 327, in search_experiments
[2025-08-20T17:49:45.291+0000] {subprocess.py:93} INFO -     exp = self._get_experiment(exp_id, view_type)
[2025-08-20T17:49:45.295+0000] {subprocess.py:93} INFO -   File "/home/***/.local/lib/python3.8/site-packages/mlflow/store/tracking/file_store.py", line 421, in _get_experiment
[2025-08-20T17:49:45.309+0000] {subprocess.py:93} INFO -     meta = FileStore._read_yaml(experiment_dir, FileStore.META_DATA_FILE_NAME)
[2025-08-20T17:49:45.311+0000] {subprocess.py:93} INFO -   File "/home/***/.local/lib/python3.8/site-packages/mlflow/store/tracking/file_store.py", line 1367, in _read_yaml
[2025-08-20T17:49:45.312+0000] {subprocess.py:93} INFO -     return _read_helper(root, file_name, attempts_remaining=retries)
[2025-08-20T17:49:45.313+0000] {subprocess.py:93} INFO -   File "/home/***/.local/lib/python3.8/site-packages/mlflow/store/tracking/file_store.py", line 1360, in _read_helper
[2025-08-20T17:49:45.315+0000] {subprocess.py:93} INFO -     result = read_yaml(root, file_name)
[2025-08-20T17:49:45.318+0000] {subprocess.py:93} INFO -   File "/home/***/.local/lib/python3.8/site-packages/mlflow/utils/file_utils.py", line 309, in read_yaml
[2025-08-20T17:49:45.320+0000] {subprocess.py:93} INFO -     raise MissingConfigException(f"Yaml file '{file_path}' does not exist.")
[2025-08-20T17:49:45.322+0000] {subprocess.py:93} INFO - mlflow.exceptions.MissingConfigException: Yaml file '/opt/***/Customer_Churn_Prediction_Pipeline/mlruns/9f8a2292aea24d39a6b035889d38fb72/meta.yaml' does not exist.
[2025-08-20T17:49:45.333+0000] {subprocess.py:93} INFO - 2025-08-20 17:49:45,308 WARNING Malformed experiment 'a20986ad69c34568ab9b4cdb0a0c41f5'. Detailed error Yaml file '/opt/***/Customer_Churn_Prediction_Pipeline/mlruns/a20986ad69c34568ab9b4cdb0a0c41f5/meta.yaml' does not exist.
[2025-08-20T17:49:45.345+0000] {subprocess.py:93} INFO - Traceback (most recent call last):
[2025-08-20T17:49:45.349+0000] {subprocess.py:93} INFO -   File "/home/***/.local/lib/python3.8/site-packages/mlflow/store/tracking/file_store.py", line 327, in search_experiments
[2025-08-20T17:49:45.384+0000] {subprocess.py:93} INFO -     exp = self._get_experiment(exp_id, view_type)
[2025-08-20T17:49:45.391+0000] {subprocess.py:93} INFO -   File "/home/***/.local/lib/python3.8/site-packages/mlflow/store/tracking/file_store.py", line 421, in _get_experiment
[2025-08-20T17:49:45.396+0000] {subprocess.py:93} INFO -     meta = FileStore._read_yaml(experiment_dir, FileStore.META_DATA_FILE_NAME)
[2025-08-20T17:49:45.400+0000] {subprocess.py:93} INFO -   File "/home/***/.local/lib/python3.8/site-packages/mlflow/store/tracking/file_store.py", line 1367, in _read_yaml
[2025-08-20T17:49:45.414+0000] {subprocess.py:93} INFO -     return _read_helper(root, file_name, attempts_remaining=retries)
[2025-08-20T17:49:45.416+0000] {subprocess.py:93} INFO -   File "/home/***/.local/lib/python3.8/site-packages/mlflow/store/tracking/file_store.py", line 1360, in _read_helper
[2025-08-20T17:49:45.418+0000] {subprocess.py:93} INFO -     result = read_yaml(root, file_name)
[2025-08-20T17:49:45.422+0000] {subprocess.py:93} INFO -   File "/home/***/.local/lib/python3.8/site-packages/mlflow/utils/file_utils.py", line 309, in read_yaml
[2025-08-20T17:49:45.428+0000] {subprocess.py:93} INFO -     raise MissingConfigException(f"Yaml file '{file_path}' does not exist.")
[2025-08-20T17:49:45.451+0000] {subprocess.py:93} INFO - mlflow.exceptions.MissingConfigException: Yaml file '/opt/***/Customer_Churn_Prediction_Pipeline/mlruns/a20986ad69c34568ab9b4cdb0a0c41f5/meta.yaml' does not exist.
[2025-08-20T17:49:45.454+0000] {subprocess.py:93} INFO - 2025-08-20 17:49:45,360 WARNING Malformed experiment 'b682dba240844ed68344d97d245b4459'. Detailed error Yaml file '/opt/***/Customer_Churn_Prediction_Pipeline/mlruns/b682dba240844ed68344d97d245b4459/meta.yaml' does not exist.
[2025-08-20T17:49:45.456+0000] {subprocess.py:93} INFO - Traceback (most recent call last):
[2025-08-20T17:49:45.462+0000] {subprocess.py:93} INFO -   File "/home/***/.local/lib/python3.8/site-packages/mlflow/store/tracking/file_store.py", line 327, in search_experiments
[2025-08-20T17:49:45.476+0000] {subprocess.py:93} INFO -     exp = self._get_experiment(exp_id, view_type)
[2025-08-20T17:49:45.487+0000] {subprocess.py:93} INFO -   File "/home/***/.local/lib/python3.8/site-packages/mlflow/store/tracking/file_store.py", line 421, in _get_experiment
[2025-08-20T17:49:45.489+0000] {subprocess.py:93} INFO -     meta = FileStore._read_yaml(experiment_dir, FileStore.META_DATA_FILE_NAME)
[2025-08-20T17:49:45.490+0000] {subprocess.py:93} INFO -   File "/home/***/.local/lib/python3.8/site-packages/mlflow/store/tracking/file_store.py", line 1367, in _read_yaml
[2025-08-20T17:49:45.494+0000] {subprocess.py:93} INFO -     return _read_helper(root, file_name, attempts_remaining=retries)
[2025-08-20T17:49:45.502+0000] {subprocess.py:93} INFO -   File "/home/***/.local/lib/python3.8/site-packages/mlflow/store/tracking/file_store.py", line 1360, in _read_helper
[2025-08-20T17:49:45.521+0000] {subprocess.py:93} INFO -     result = read_yaml(root, file_name)
[2025-08-20T17:49:45.529+0000] {subprocess.py:93} INFO -   File "/home/***/.local/lib/python3.8/site-packages/mlflow/utils/file_utils.py", line 309, in read_yaml
[2025-08-20T17:49:45.541+0000] {subprocess.py:93} INFO -     raise MissingConfigException(f"Yaml file '{file_path}' does not exist.")
[2025-08-20T17:49:45.565+0000] {subprocess.py:93} INFO - mlflow.exceptions.MissingConfigException: Yaml file '/opt/***/Customer_Churn_Prediction_Pipeline/mlruns/b682dba240844ed68344d97d245b4459/meta.yaml' does not exist.
[2025-08-20T17:49:45.585+0000] {subprocess.py:93} INFO - 2025-08-20 17:49:45,567 WARNING Malformed experiment 'e45a2c3f2fe5435bb5ee5c51f9930955'. Detailed error Yaml file '/opt/***/Customer_Churn_Prediction_Pipeline/mlruns/e45a2c3f2fe5435bb5ee5c51f9930955/meta.yaml' does not exist.
[2025-08-20T17:49:45.601+0000] {subprocess.py:93} INFO - Traceback (most recent call last):
[2025-08-20T17:49:45.633+0000] {subprocess.py:93} INFO -   File "/home/***/.local/lib/python3.8/site-packages/mlflow/store/tracking/file_store.py", line 327, in search_experiments
[2025-08-20T17:49:45.634+0000] {subprocess.py:93} INFO -     exp = self._get_experiment(exp_id, view_type)
[2025-08-20T17:49:45.681+0000] {subprocess.py:93} INFO -   File "/home/***/.local/lib/python3.8/site-packages/mlflow/store/tracking/file_store.py", line 421, in _get_experiment
[2025-08-20T17:49:45.695+0000] {subprocess.py:93} INFO -     meta = FileStore._read_yaml(experiment_dir, FileStore.META_DATA_FILE_NAME)
[2025-08-20T17:49:45.713+0000] {subprocess.py:93} INFO -   File "/home/***/.local/lib/python3.8/site-packages/mlflow/store/tracking/file_store.py", line 1367, in _read_yaml
[2025-08-20T17:49:45.763+0000] {subprocess.py:93} INFO -     return _read_helper(root, file_name, attempts_remaining=retries)
[2025-08-20T17:49:45.780+0000] {subprocess.py:93} INFO -   File "/home/***/.local/lib/python3.8/site-packages/mlflow/store/tracking/file_store.py", line 1360, in _read_helper
[2025-08-20T17:49:45.797+0000] {subprocess.py:93} INFO -     result = read_yaml(root, file_name)
[2025-08-20T17:49:45.826+0000] {subprocess.py:93} INFO -   File "/home/***/.local/lib/python3.8/site-packages/mlflow/utils/file_utils.py", line 309, in read_yaml
[2025-08-20T17:49:45.838+0000] {subprocess.py:93} INFO -     raise MissingConfigException(f"Yaml file '{file_path}' does not exist.")
[2025-08-20T17:49:45.845+0000] {subprocess.py:93} INFO - mlflow.exceptions.MissingConfigException: Yaml file '/opt/***/Customer_Churn_Prediction_Pipeline/mlruns/e45a2c3f2fe5435bb5ee5c51f9930955/meta.yaml' does not exist.
[2025-08-20T17:49:46.398+0000] {subprocess.py:93} INFO - 2025-08-20 17:49:46,391 WARNING Malformed experiment '3c451db2cddf461b9fa24b573ecdc116'. Detailed error Yaml file '/opt/***/Customer_Churn_Prediction_Pipeline/mlruns/3c451db2cddf461b9fa24b573ecdc116/meta.yaml' does not exist.
[2025-08-20T17:49:46.421+0000] {subprocess.py:93} INFO - Traceback (most recent call last):
[2025-08-20T17:49:46.432+0000] {subprocess.py:93} INFO -   File "/home/***/.local/lib/python3.8/site-packages/mlflow/store/tracking/file_store.py", line 327, in search_experiments
[2025-08-20T17:49:46.435+0000] {subprocess.py:93} INFO -     exp = self._get_experiment(exp_id, view_type)
[2025-08-20T17:49:46.441+0000] {subprocess.py:93} INFO -   File "/home/***/.local/lib/python3.8/site-packages/mlflow/store/tracking/file_store.py", line 421, in _get_experiment
[2025-08-20T17:49:46.445+0000] {subprocess.py:93} INFO -     meta = FileStore._read_yaml(experiment_dir, FileStore.META_DATA_FILE_NAME)
[2025-08-20T17:49:46.452+0000] {subprocess.py:93} INFO -   File "/home/***/.local/lib/python3.8/site-packages/mlflow/store/tracking/file_store.py", line 1367, in _read_yaml
[2025-08-20T17:49:46.463+0000] {subprocess.py:93} INFO -     return _read_helper(root, file_name, attempts_remaining=retries)
[2025-08-20T17:49:46.464+0000] {subprocess.py:93} INFO -   File "/home/***/.local/lib/python3.8/site-packages/mlflow/store/tracking/file_store.py", line 1360, in _read_helper
[2025-08-20T17:49:46.467+0000] {subprocess.py:93} INFO -     result = read_yaml(root, file_name)
[2025-08-20T17:49:46.470+0000] {subprocess.py:93} INFO -   File "/home/***/.local/lib/python3.8/site-packages/mlflow/utils/file_utils.py", line 309, in read_yaml
[2025-08-20T17:49:46.473+0000] {subprocess.py:93} INFO -     raise MissingConfigException(f"Yaml file '{file_path}' does not exist.")
[2025-08-20T17:49:46.485+0000] {subprocess.py:93} INFO - mlflow.exceptions.MissingConfigException: Yaml file '/opt/***/Customer_Churn_Prediction_Pipeline/mlruns/3c451db2cddf461b9fa24b573ecdc116/meta.yaml' does not exist.
[2025-08-20T17:49:46.661+0000] {subprocess.py:93} INFO - 2025-08-20 17:49:46,661 WARNING Malformed experiment '66a6a96d2c6e463cbcf97c942dce679d'. Detailed error Yaml file '/opt/***/Customer_Churn_Prediction_Pipeline/mlruns/66a6a96d2c6e463cbcf97c942dce679d/meta.yaml' does not exist.
[2025-08-20T17:49:46.663+0000] {subprocess.py:93} INFO - Traceback (most recent call last):
[2025-08-20T17:49:46.666+0000] {subprocess.py:93} INFO -   File "/home/***/.local/lib/python3.8/site-packages/mlflow/store/tracking/file_store.py", line 327, in search_experiments
[2025-08-20T17:49:46.673+0000] {subprocess.py:93} INFO -     exp = self._get_experiment(exp_id, view_type)
[2025-08-20T17:49:46.681+0000] {subprocess.py:93} INFO -   File "/home/***/.local/lib/python3.8/site-packages/mlflow/store/tracking/file_store.py", line 421, in _get_experiment
[2025-08-20T17:49:46.685+0000] {subprocess.py:93} INFO -     meta = FileStore._read_yaml(experiment_dir, FileStore.META_DATA_FILE_NAME)
[2025-08-20T17:49:46.688+0000] {subprocess.py:93} INFO -   File "/home/***/.local/lib/python3.8/site-packages/mlflow/store/tracking/file_store.py", line 1367, in _read_yaml
[2025-08-20T17:49:46.705+0000] {subprocess.py:93} INFO -     return _read_helper(root, file_name, attempts_remaining=retries)
[2025-08-20T17:49:46.723+0000] {subprocess.py:93} INFO -   File "/home/***/.local/lib/python3.8/site-packages/mlflow/store/tracking/file_store.py", line 1360, in _read_helper
[2025-08-20T17:49:46.725+0000] {subprocess.py:93} INFO -     result = read_yaml(root, file_name)
[2025-08-20T17:49:46.734+0000] {subprocess.py:93} INFO -   File "/home/***/.local/lib/python3.8/site-packages/mlflow/utils/file_utils.py", line 309, in read_yaml
[2025-08-20T17:49:46.740+0000] {subprocess.py:93} INFO -     raise MissingConfigException(f"Yaml file '{file_path}' does not exist.")
[2025-08-20T17:49:46.760+0000] {subprocess.py:93} INFO - mlflow.exceptions.MissingConfigException: Yaml file '/opt/***/Customer_Churn_Prediction_Pipeline/mlruns/66a6a96d2c6e463cbcf97c942dce679d/meta.yaml' does not exist.
[2025-08-20T17:49:46.761+0000] {subprocess.py:93} INFO - 2025-08-20 17:49:46,752 WARNING Malformed experiment '758f77ef4c794795bdfdff4c02503bcc'. Detailed error Yaml file '/opt/***/Customer_Churn_Prediction_Pipeline/mlruns/758f77ef4c794795bdfdff4c02503bcc/meta.yaml' does not exist.
[2025-08-20T17:49:46.765+0000] {subprocess.py:93} INFO - Traceback (most recent call last):
[2025-08-20T17:49:46.768+0000] {subprocess.py:93} INFO -   File "/home/***/.local/lib/python3.8/site-packages/mlflow/store/tracking/file_store.py", line 327, in search_experiments
[2025-08-20T17:49:46.770+0000] {subprocess.py:93} INFO -     exp = self._get_experiment(exp_id, view_type)
[2025-08-20T17:49:46.779+0000] {subprocess.py:93} INFO -   File "/home/***/.local/lib/python3.8/site-packages/mlflow/store/tracking/file_store.py", line 421, in _get_experiment
[2025-08-20T17:49:46.791+0000] {subprocess.py:93} INFO -     meta = FileStore._read_yaml(experiment_dir, FileStore.META_DATA_FILE_NAME)
[2025-08-20T17:49:46.795+0000] {subprocess.py:93} INFO -   File "/home/***/.local/lib/python3.8/site-packages/mlflow/store/tracking/file_store.py", line 1367, in _read_yaml
[2025-08-20T17:49:46.798+0000] {subprocess.py:93} INFO -     return _read_helper(root, file_name, attempts_remaining=retries)
[2025-08-20T17:49:46.803+0000] {subprocess.py:93} INFO -   File "/home/***/.local/lib/python3.8/site-packages/mlflow/store/tracking/file_store.py", line 1360, in _read_helper
[2025-08-20T17:49:46.808+0000] {subprocess.py:93} INFO -     result = read_yaml(root, file_name)
[2025-08-20T17:49:46.815+0000] {subprocess.py:93} INFO -   File "/home/***/.local/lib/python3.8/site-packages/mlflow/utils/file_utils.py", line 309, in read_yaml
[2025-08-20T17:49:46.835+0000] {subprocess.py:93} INFO -     raise MissingConfigException(f"Yaml file '{file_path}' does not exist.")
[2025-08-20T17:49:46.842+0000] {subprocess.py:93} INFO - mlflow.exceptions.MissingConfigException: Yaml file '/opt/***/Customer_Churn_Prediction_Pipeline/mlruns/758f77ef4c794795bdfdff4c02503bcc/meta.yaml' does not exist.
[2025-08-20T17:49:46.844+0000] {subprocess.py:93} INFO - 2025-08-20 17:49:46,799 WARNING Malformed experiment '7a4c300b24d14505ba7f4df32748abf9'. Detailed error Yaml file '/opt/***/Customer_Churn_Prediction_Pipeline/mlruns/7a4c300b24d14505ba7f4df32748abf9/meta.yaml' does not exist.
[2025-08-20T17:49:46.866+0000] {subprocess.py:93} INFO - Traceback (most recent call last):
[2025-08-20T17:49:46.869+0000] {subprocess.py:93} INFO -   File "/home/***/.local/lib/python3.8/site-packages/mlflow/store/tracking/file_store.py", line 327, in search_experiments
[2025-08-20T17:49:46.871+0000] {subprocess.py:93} INFO -     exp = self._get_experiment(exp_id, view_type)
[2025-08-20T17:49:46.880+0000] {subprocess.py:93} INFO -   File "/home/***/.local/lib/python3.8/site-packages/mlflow/store/tracking/file_store.py", line 421, in _get_experiment
[2025-08-20T17:49:46.884+0000] {subprocess.py:93} INFO -     meta = FileStore._read_yaml(experiment_dir, FileStore.META_DATA_FILE_NAME)
[2025-08-20T17:49:46.899+0000] {subprocess.py:93} INFO -   File "/home/***/.local/lib/python3.8/site-packages/mlflow/store/tracking/file_store.py", line 1367, in _read_yaml
[2025-08-20T17:49:46.900+0000] {subprocess.py:93} INFO -     return _read_helper(root, file_name, attempts_remaining=retries)
[2025-08-20T17:49:46.902+0000] {subprocess.py:93} INFO -   File "/home/***/.local/lib/python3.8/site-packages/mlflow/store/tracking/file_store.py", line 1360, in _read_helper
[2025-08-20T17:49:46.906+0000] {subprocess.py:93} INFO -     result = read_yaml(root, file_name)
[2025-08-20T17:49:46.907+0000] {subprocess.py:93} INFO -   File "/home/***/.local/lib/python3.8/site-packages/mlflow/utils/file_utils.py", line 309, in read_yaml
[2025-08-20T17:49:46.913+0000] {subprocess.py:93} INFO -     raise MissingConfigException(f"Yaml file '{file_path}' does not exist.")
[2025-08-20T17:49:46.925+0000] {subprocess.py:93} INFO - mlflow.exceptions.MissingConfigException: Yaml file '/opt/***/Customer_Churn_Prediction_Pipeline/mlruns/7a4c300b24d14505ba7f4df32748abf9/meta.yaml' does not exist.
[2025-08-20T17:49:46.936+0000] {subprocess.py:93} INFO - 2025-08-20 17:49:46,898 WARNING Malformed experiment '7fd6ebbc25ba485ba1086b06b2552e0e'. Detailed error Yaml file '/opt/***/Customer_Churn_Prediction_Pipeline/mlruns/7fd6ebbc25ba485ba1086b06b2552e0e/meta.yaml' does not exist.
[2025-08-20T17:49:46.939+0000] {subprocess.py:93} INFO - Traceback (most recent call last):
[2025-08-20T17:49:46.941+0000] {subprocess.py:93} INFO -   File "/home/***/.local/lib/python3.8/site-packages/mlflow/store/tracking/file_store.py", line 327, in search_experiments
[2025-08-20T17:49:46.961+0000] {subprocess.py:93} INFO -     exp = self._get_experiment(exp_id, view_type)
[2025-08-20T17:49:46.975+0000] {subprocess.py:93} INFO -   File "/home/***/.local/lib/python3.8/site-packages/mlflow/store/tracking/file_store.py", line 421, in _get_experiment
[2025-08-20T17:49:46.977+0000] {subprocess.py:93} INFO -     meta = FileStore._read_yaml(experiment_dir, FileStore.META_DATA_FILE_NAME)
[2025-08-20T17:49:46.980+0000] {subprocess.py:93} INFO -   File "/home/***/.local/lib/python3.8/site-packages/mlflow/store/tracking/file_store.py", line 1367, in _read_yaml
[2025-08-20T17:49:46.988+0000] {subprocess.py:93} INFO -     return _read_helper(root, file_name, attempts_remaining=retries)
[2025-08-20T17:49:46.995+0000] {subprocess.py:93} INFO -   File "/home/***/.local/lib/python3.8/site-packages/mlflow/store/tracking/file_store.py", line 1360, in _read_helper
[2025-08-20T17:49:47.017+0000] {subprocess.py:93} INFO -     result = read_yaml(root, file_name)
[2025-08-20T17:49:47.022+0000] {subprocess.py:93} INFO -   File "/home/***/.local/lib/python3.8/site-packages/mlflow/utils/file_utils.py", line 309, in read_yaml
[2025-08-20T17:49:47.024+0000] {subprocess.py:93} INFO -     raise MissingConfigException(f"Yaml file '{file_path}' does not exist.")
[2025-08-20T17:49:47.026+0000] {subprocess.py:93} INFO - mlflow.exceptions.MissingConfigException: Yaml file '/opt/***/Customer_Churn_Prediction_Pipeline/mlruns/7fd6ebbc25ba485ba1086b06b2552e0e/meta.yaml' does not exist.
[2025-08-20T17:49:47.028+0000] {subprocess.py:93} INFO - 2025-08-20 17:49:46,937 WARNING Malformed experiment '9f8a2292aea24d39a6b035889d38fb72'. Detailed error Yaml file '/opt/***/Customer_Churn_Prediction_Pipeline/mlruns/9f8a2292aea24d39a6b035889d38fb72/meta.yaml' does not exist.
[2025-08-20T17:49:47.040+0000] {subprocess.py:93} INFO - Traceback (most recent call last):
[2025-08-20T17:49:47.049+0000] {subprocess.py:93} INFO -   File "/home/***/.local/lib/python3.8/site-packages/mlflow/store/tracking/file_store.py", line 327, in search_experiments
[2025-08-20T17:49:47.051+0000] {subprocess.py:93} INFO -     exp = self._get_experiment(exp_id, view_type)
[2025-08-20T17:49:47.056+0000] {subprocess.py:93} INFO -   File "/home/***/.local/lib/python3.8/site-packages/mlflow/store/tracking/file_store.py", line 421, in _get_experiment
[2025-08-20T17:49:47.061+0000] {subprocess.py:93} INFO -     meta = FileStore._read_yaml(experiment_dir, FileStore.META_DATA_FILE_NAME)
[2025-08-20T17:49:47.062+0000] {subprocess.py:93} INFO -   File "/home/***/.local/lib/python3.8/site-packages/mlflow/store/tracking/file_store.py", line 1367, in _read_yaml
[2025-08-20T17:49:47.071+0000] {subprocess.py:93} INFO -     return _read_helper(root, file_name, attempts_remaining=retries)
[2025-08-20T17:49:47.077+0000] {subprocess.py:93} INFO -   File "/home/***/.local/lib/python3.8/site-packages/mlflow/store/tracking/file_store.py", line 1360, in _read_helper
[2025-08-20T17:49:47.082+0000] {subprocess.py:93} INFO -     result = read_yaml(root, file_name)
[2025-08-20T17:49:47.083+0000] {subprocess.py:93} INFO -   File "/home/***/.local/lib/python3.8/site-packages/mlflow/utils/file_utils.py", line 309, in read_yaml
[2025-08-20T17:49:47.085+0000] {subprocess.py:93} INFO -     raise MissingConfigException(f"Yaml file '{file_path}' does not exist.")
[2025-08-20T17:49:47.086+0000] {subprocess.py:93} INFO - mlflow.exceptions.MissingConfigException: Yaml file '/opt/***/Customer_Churn_Prediction_Pipeline/mlruns/9f8a2292aea24d39a6b035889d38fb72/meta.yaml' does not exist.
[2025-08-20T17:49:47.093+0000] {subprocess.py:93} INFO - 2025-08-20 17:49:46,978 WARNING Malformed experiment 'a20986ad69c34568ab9b4cdb0a0c41f5'. Detailed error Yaml file '/opt/***/Customer_Churn_Prediction_Pipeline/mlruns/a20986ad69c34568ab9b4cdb0a0c41f5/meta.yaml' does not exist.
[2025-08-20T17:49:47.096+0000] {subprocess.py:93} INFO - Traceback (most recent call last):
[2025-08-20T17:49:47.097+0000] {subprocess.py:93} INFO -   File "/home/***/.local/lib/python3.8/site-packages/mlflow/store/tracking/file_store.py", line 327, in search_experiments
[2025-08-20T17:49:47.105+0000] {subprocess.py:93} INFO -     exp = self._get_experiment(exp_id, view_type)
[2025-08-20T17:49:47.108+0000] {subprocess.py:93} INFO -   File "/home/***/.local/lib/python3.8/site-packages/mlflow/store/tracking/file_store.py", line 421, in _get_experiment
[2025-08-20T17:49:47.113+0000] {subprocess.py:93} INFO -     meta = FileStore._read_yaml(experiment_dir, FileStore.META_DATA_FILE_NAME)
[2025-08-20T17:49:47.114+0000] {subprocess.py:93} INFO -   File "/home/***/.local/lib/python3.8/site-packages/mlflow/store/tracking/file_store.py", line 1367, in _read_yaml
[2025-08-20T17:49:47.116+0000] {subprocess.py:93} INFO -     return _read_helper(root, file_name, attempts_remaining=retries)
[2025-08-20T17:49:47.117+0000] {subprocess.py:93} INFO -   File "/home/***/.local/lib/python3.8/site-packages/mlflow/store/tracking/file_store.py", line 1360, in _read_helper
[2025-08-20T17:49:47.119+0000] {subprocess.py:93} INFO -     result = read_yaml(root, file_name)
[2025-08-20T17:49:47.121+0000] {subprocess.py:93} INFO -   File "/home/***/.local/lib/python3.8/site-packages/mlflow/utils/file_utils.py", line 309, in read_yaml
[2025-08-20T17:49:47.123+0000] {subprocess.py:93} INFO -     raise MissingConfigException(f"Yaml file '{file_path}' does not exist.")
[2025-08-20T17:49:47.125+0000] {subprocess.py:93} INFO - mlflow.exceptions.MissingConfigException: Yaml file '/opt/***/Customer_Churn_Prediction_Pipeline/mlruns/a20986ad69c34568ab9b4cdb0a0c41f5/meta.yaml' does not exist.
[2025-08-20T17:49:47.126+0000] {subprocess.py:93} INFO - 2025-08-20 17:49:47,043 WARNING Malformed experiment 'b682dba240844ed68344d97d245b4459'. Detailed error Yaml file '/opt/***/Customer_Churn_Prediction_Pipeline/mlruns/b682dba240844ed68344d97d245b4459/meta.yaml' does not exist.
[2025-08-20T17:49:47.128+0000] {subprocess.py:93} INFO - Traceback (most recent call last):
[2025-08-20T17:49:47.131+0000] {subprocess.py:93} INFO -   File "/home/***/.local/lib/python3.8/site-packages/mlflow/store/tracking/file_store.py", line 327, in search_experiments
[2025-08-20T17:49:47.133+0000] {subprocess.py:93} INFO -     exp = self._get_experiment(exp_id, view_type)
[2025-08-20T17:49:47.134+0000] {subprocess.py:93} INFO -   File "/home/***/.local/lib/python3.8/site-packages/mlflow/store/tracking/file_store.py", line 421, in _get_experiment
[2025-08-20T17:49:47.135+0000] {subprocess.py:93} INFO -     meta = FileStore._read_yaml(experiment_dir, FileStore.META_DATA_FILE_NAME)
[2025-08-20T17:49:47.136+0000] {subprocess.py:93} INFO -   File "/home/***/.local/lib/python3.8/site-packages/mlflow/store/tracking/file_store.py", line 1367, in _read_yaml
[2025-08-20T17:49:47.157+0000] {subprocess.py:93} INFO -     return _read_helper(root, file_name, attempts_remaining=retries)
[2025-08-20T17:49:47.161+0000] {subprocess.py:93} INFO -   File "/home/***/.local/lib/python3.8/site-packages/mlflow/store/tracking/file_store.py", line 1360, in _read_helper
[2025-08-20T17:49:47.162+0000] {subprocess.py:93} INFO -     result = read_yaml(root, file_name)
[2025-08-20T17:49:47.165+0000] {subprocess.py:93} INFO -   File "/home/***/.local/lib/python3.8/site-packages/mlflow/utils/file_utils.py", line 309, in read_yaml
[2025-08-20T17:49:47.168+0000] {subprocess.py:93} INFO -     raise MissingConfigException(f"Yaml file '{file_path}' does not exist.")
[2025-08-20T17:49:47.170+0000] {subprocess.py:93} INFO - mlflow.exceptions.MissingConfigException: Yaml file '/opt/***/Customer_Churn_Prediction_Pipeline/mlruns/b682dba240844ed68344d97d245b4459/meta.yaml' does not exist.
[2025-08-20T17:49:47.172+0000] {subprocess.py:93} INFO - 2025-08-20 17:49:47,120 WARNING Malformed experiment 'e45a2c3f2fe5435bb5ee5c51f9930955'. Detailed error Yaml file '/opt/***/Customer_Churn_Prediction_Pipeline/mlruns/e45a2c3f2fe5435bb5ee5c51f9930955/meta.yaml' does not exist.
[2025-08-20T17:49:47.185+0000] {subprocess.py:93} INFO - Traceback (most recent call last):
[2025-08-20T17:49:47.189+0000] {subprocess.py:93} INFO -   File "/home/***/.local/lib/python3.8/site-packages/mlflow/store/tracking/file_store.py", line 327, in search_experiments
[2025-08-20T17:49:47.191+0000] {subprocess.py:93} INFO -     exp = self._get_experiment(exp_id, view_type)
[2025-08-20T17:49:47.193+0000] {subprocess.py:93} INFO -   File "/home/***/.local/lib/python3.8/site-packages/mlflow/store/tracking/file_store.py", line 421, in _get_experiment
[2025-08-20T17:49:47.194+0000] {subprocess.py:93} INFO -     meta = FileStore._read_yaml(experiment_dir, FileStore.META_DATA_FILE_NAME)
[2025-08-20T17:49:47.197+0000] {subprocess.py:93} INFO -   File "/home/***/.local/lib/python3.8/site-packages/mlflow/store/tracking/file_store.py", line 1367, in _read_yaml
[2025-08-20T17:49:47.198+0000] {subprocess.py:93} INFO -     return _read_helper(root, file_name, attempts_remaining=retries)
[2025-08-20T17:49:47.204+0000] {subprocess.py:93} INFO -   File "/home/***/.local/lib/python3.8/site-packages/mlflow/store/tracking/file_store.py", line 1360, in _read_helper
[2025-08-20T17:49:47.206+0000] {subprocess.py:93} INFO -     result = read_yaml(root, file_name)
[2025-08-20T17:49:47.208+0000] {subprocess.py:93} INFO -   File "/home/***/.local/lib/python3.8/site-packages/mlflow/utils/file_utils.py", line 309, in read_yaml
[2025-08-20T17:49:47.215+0000] {subprocess.py:93} INFO -     raise MissingConfigException(f"Yaml file '{file_path}' does not exist.")
[2025-08-20T17:49:47.217+0000] {subprocess.py:93} INFO - mlflow.exceptions.MissingConfigException: Yaml file '/opt/***/Customer_Churn_Prediction_Pipeline/mlruns/e45a2c3f2fe5435bb5ee5c51f9930955/meta.yaml' does not exist.
[2025-08-20T17:49:47.220+0000] {subprocess.py:93} INFO - 2025-08-20 17:49:47,124 INFO Loading features and target from feature store...
[2025-08-20T17:49:47.226+0000] {subprocess.py:93} INFO - 2025-08-20 17:49:47,124 INFO Connecting to SQLite DB at data/features/churn_features.db
[2025-08-20T17:49:47.229+0000] {subprocess.py:93} INFO - 2025-08-20 17:49:47,196 INFO Available tables: ['churn_features']
[2025-08-20T17:49:48.289+0000] {subprocess.py:93} INFO - 2025-08-20 17:49:48,288 INFO Retrieved 7032 rows and 36 columns from table churn_features
[2025-08-20T17:49:48.305+0000] {subprocess.py:93} INFO - 2025-08-20 17:49:48,294 INFO Found target column 'Churn'. Processing...
[2025-08-20T17:49:48.320+0000] {subprocess.py:93} INFO - 2025-08-20 17:49:48,294 INFO Raw target column stats:
[2025-08-20T17:49:48.326+0000] {subprocess.py:93} INFO - 2025-08-20 17:49:48,294 INFO   - Type: float64
[2025-08-20T17:49:48.333+0000] {subprocess.py:93} INFO - 2025-08-20 17:49:48,295 INFO   - Unique values: [-0.601663392508594, 1.6620589061112205]
[2025-08-20T17:49:48.343+0000] {subprocess.py:93} INFO - 2025-08-20 17:49:48,314 INFO   - Value counts:
[2025-08-20T17:49:48.350+0000] {subprocess.py:93} INFO - -0.601663    5163
[2025-08-20T17:49:48.351+0000] {subprocess.py:93} INFO -  1.662059    1869
[2025-08-20T17:49:48.359+0000] {subprocess.py:93} INFO - Name: Churn, dtype: int64
[2025-08-20T17:49:48.363+0000] {subprocess.py:93} INFO - 2025-08-20 17:49:48,323 INFO Original target values before normalization: -0.601663    5163
[2025-08-20T17:49:48.367+0000] {subprocess.py:93} INFO -  1.662059    1869
[2025-08-20T17:49:48.368+0000] {subprocess.py:93} INFO - Name: Churn, dtype: int64
[2025-08-20T17:49:48.390+0000] {subprocess.py:93} INFO - 2025-08-20 17:49:48,323 INFO Original target dtype: float64
[2025-08-20T17:49:48.398+0000] {subprocess.py:93} INFO - 2025-08-20 17:49:48,324 INFO Unique numeric values in target: [-0.601663392508594, 1.6620589061112205]
[2025-08-20T17:49:48.401+0000] {subprocess.py:93} INFO - 2025-08-20 17:49:48,325 INFO Binary target with values [-0.601663392508594, 1.6620589061112205]. Mapping to (0,1).
[2025-08-20T17:49:48.402+0000] {subprocess.py:93} INFO - 2025-08-20 17:49:48,329 INFO Mapped -0.601663392508594→0, 1.6620589061112205→1
[2025-08-20T17:49:48.403+0000] {subprocess.py:93} INFO - 2025-08-20 17:49:48,331 INFO Final normalized target stats:
[2025-08-20T17:49:48.405+0000] {subprocess.py:93} INFO - 2025-08-20 17:49:48,332 INFO   - Unique values: [0, 1]
[2025-08-20T17:49:48.407+0000] {subprocess.py:93} INFO - 2025-08-20 17:49:48,346 INFO   - Value counts:
[2025-08-20T17:49:48.421+0000] {subprocess.py:93} INFO - 0    5163
[2025-08-20T17:49:48.425+0000] {subprocess.py:93} INFO - 1    1869
[2025-08-20T17:49:48.427+0000] {subprocess.py:93} INFO - Name: Churn, dtype: int64
[2025-08-20T17:49:48.429+0000] {subprocess.py:93} INFO - 2025-08-20 17:49:48,347 INFO Features shape before dtype fix: (7032, 35), Target shape: (7032,)
[2025-08-20T17:49:48.440+0000] {subprocess.py:93} INFO - 2025-08-20 17:49:48,439 INFO Features dtypes after fix:
[2025-08-20T17:49:48.445+0000] {subprocess.py:93} INFO - gender                                   float64
[2025-08-20T17:49:48.466+0000] {subprocess.py:93} INFO - SeniorCitizen                            float64
[2025-08-20T17:49:48.468+0000] {subprocess.py:93} INFO - Partner                                  float64
[2025-08-20T17:49:48.474+0000] {subprocess.py:93} INFO - Dependents                               float64
[2025-08-20T17:49:48.482+0000] {subprocess.py:93} INFO - tenure                                   float64
[2025-08-20T17:49:48.503+0000] {subprocess.py:93} INFO - PhoneService                             float64
[2025-08-20T17:49:48.511+0000] {subprocess.py:93} INFO - PaperlessBilling                         float64
[2025-08-20T17:49:48.522+0000] {subprocess.py:93} INFO - MonthlyCharges                           float64
[2025-08-20T17:49:48.534+0000] {subprocess.py:93} INFO - TotalCharges                             float64
[2025-08-20T17:49:48.537+0000] {subprocess.py:93} INFO - TotalChargesPerTenure                    float64
[2025-08-20T17:49:48.540+0000] {subprocess.py:93} INFO - MultipleLines_No phone service           float64
[2025-08-20T17:49:48.544+0000] {subprocess.py:93} INFO - MultipleLines_Yes                        float64
[2025-08-20T17:49:48.547+0000] {subprocess.py:93} INFO - InternetService_Fiber optic              float64
[2025-08-20T17:49:48.548+0000] {subprocess.py:93} INFO - InternetService_No                       float64
[2025-08-20T17:49:48.549+0000] {subprocess.py:93} INFO - OnlineSecurity_No internet service       float64
[2025-08-20T17:49:48.551+0000] {subprocess.py:93} INFO - OnlineSecurity_Yes                       float64
[2025-08-20T17:49:48.556+0000] {subprocess.py:93} INFO - OnlineBackup_No internet service         float64
[2025-08-20T17:49:48.558+0000] {subprocess.py:93} INFO - OnlineBackup_Yes                         float64
[2025-08-20T17:49:48.564+0000] {subprocess.py:93} INFO - DeviceProtection_No internet service     float64
[2025-08-20T17:49:48.568+0000] {subprocess.py:93} INFO - DeviceProtection_Yes                     float64
[2025-08-20T17:49:48.570+0000] {subprocess.py:93} INFO - TechSupport_No internet service          float64
[2025-08-20T17:49:48.572+0000] {subprocess.py:93} INFO - TechSupport_Yes                          float64
[2025-08-20T17:49:48.573+0000] {subprocess.py:93} INFO - StreamingTV_No internet service          float64
[2025-08-20T17:49:48.574+0000] {subprocess.py:93} INFO - StreamingTV_Yes                          float64
[2025-08-20T17:49:48.575+0000] {subprocess.py:93} INFO - StreamingMovies_No internet service      float64
[2025-08-20T17:49:48.576+0000] {subprocess.py:93} INFO - StreamingMovies_Yes                      float64
[2025-08-20T17:49:48.577+0000] {subprocess.py:93} INFO - Contract_One year                        float64
[2025-08-20T17:49:48.584+0000] {subprocess.py:93} INFO - Contract_Two year                        float64
[2025-08-20T17:49:48.585+0000] {subprocess.py:93} INFO - PaymentMethod_Credit card (automatic)    float64
[2025-08-20T17:49:48.588+0000] {subprocess.py:93} INFO - PaymentMethod_Electronic check           float64
[2025-08-20T17:49:48.593+0000] {subprocess.py:93} INFO - PaymentMethod_Mailed check               float64
[2025-08-20T17:49:48.604+0000] {subprocess.py:93} INFO - TenureGroup_13-24                        float64
[2025-08-20T17:49:48.605+0000] {subprocess.py:93} INFO - TenureGroup_25-48                        float64
[2025-08-20T17:49:48.613+0000] {subprocess.py:93} INFO - TenureGroup_49-60                        float64
[2025-08-20T17:49:48.622+0000] {subprocess.py:93} INFO - TenureGroup_61+                          float64
[2025-08-20T17:49:48.628+0000] {subprocess.py:93} INFO - dtype: object
[2025-08-20T17:49:48.631+0000] {subprocess.py:93} INFO - 2025-08-20 17:49:48,447 INFO Unique classes in target: [0 1]
[2025-08-20T17:49:48.636+0000] {subprocess.py:93} INFO - 2025-08-20 17:49:48,449 INFO Class distribution: [5163 1869]
[2025-08-20T17:49:53.175+0000] {subprocess.py:93} INFO - 2025-08-20 17:49:53,174 INFO Logistic Regression recall=0.7807, acc=0.7306, prec=0.4958, f1=0.6064
[2025-08-20T17:49:53.214+0000] {subprocess.py:93} INFO - 2025-08-20 17:49:53,214 INFO Classification report:
[2025-08-20T17:49:53.216+0000] {subprocess.py:93} INFO -               precision    recall  f1-score   support
[2025-08-20T17:49:53.222+0000] {subprocess.py:93} INFO - 
[2025-08-20T17:49:53.223+0000] {subprocess.py:93} INFO -            0       0.90      0.71      0.80      1033
[2025-08-20T17:49:53.224+0000] {subprocess.py:93} INFO -            1       0.50      0.78      0.61       374
[2025-08-20T17:49:53.226+0000] {subprocess.py:93} INFO - 
[2025-08-20T17:49:53.227+0000] {subprocess.py:93} INFO -     accuracy                           0.73      1407
[2025-08-20T17:49:53.228+0000] {subprocess.py:93} INFO -    macro avg       0.70      0.75      0.70      1407
[2025-08-20T17:49:53.230+0000] {subprocess.py:93} INFO - weighted avg       0.79      0.73      0.75      1407
[2025-08-20T17:49:53.231+0000] {subprocess.py:93} INFO - 
[2025-08-20T17:50:00.145+0000] {subprocess.py:93} INFO - 2025-08-20 17:50:00,144 INFO RandomForest recall=0.4733, acc=0.7953, prec=0.6604, f1=0.5514
[2025-08-20T17:50:00.194+0000] {subprocess.py:93} INFO - 2025-08-20 17:50:00,193 INFO Classification report:
[2025-08-20T17:50:00.196+0000] {subprocess.py:93} INFO -               precision    recall  f1-score   support
[2025-08-20T17:50:00.198+0000] {subprocess.py:93} INFO - 
[2025-08-20T17:50:00.200+0000] {subprocess.py:93} INFO -            0       0.83      0.91      0.87      1033
[2025-08-20T17:50:00.203+0000] {subprocess.py:93} INFO -            1       0.66      0.47      0.55       374
[2025-08-20T17:50:00.207+0000] {subprocess.py:93} INFO - 
[2025-08-20T17:50:00.208+0000] {subprocess.py:93} INFO -     accuracy                           0.80      1407
[2025-08-20T17:50:00.209+0000] {subprocess.py:93} INFO -    macro avg       0.74      0.69      0.71      1407
[2025-08-20T17:50:00.211+0000] {subprocess.py:93} INFO - weighted avg       0.78      0.80      0.78      1407
[2025-08-20T17:50:00.212+0000] {subprocess.py:93} INFO - 
[2025-08-20T17:50:00.360+0000] {subprocess.py:93} INFO - 2025-08-20 17:50:00,360 INFO Best model (LogisticRegression) saved locally to models/churn_model.pkl with recall=0.7807
[2025-08-20T17:50:00.361+0000] {subprocess.py:93} INFO - 2025-08-20 17:50:00,361 INFO Best run_id written to /tmp/best_run_id.txt
[2025-08-20T17:50:43.655+0000] {subprocess.py:93} INFO - /home/***/.local/lib/python3.8/site-packages/mlflow/types/utils.py:407: UserWarning: Hint: Inferred schema contains integer column(s). Integer columns in Python cannot represent missing values. If your input data contains missing values at inference time, it will be encoded as floats and will cause a schema enforcement error. The best way to avoid this problem is to infer the model schema based on a realistic data sample (training dataset) that includes missing values. Alternatively, you can declare integer columns as doubles (float64) whenever these columns may have missing values. See `Handling Integers With Missing Values <https://www.mlflow.org/docs/latest/models.html#handling-integers-with-missing-values>`_ for more details.
[2025-08-20T17:50:43.657+0000] {subprocess.py:93} INFO -   warnings.warn(
[2025-08-20T17:50:43.659+0000] {subprocess.py:93} INFO - Registered model 'churn_model' already exists. Creating a new version of this model...
[2025-08-20T17:50:43.661+0000] {subprocess.py:93} INFO - 2025-08-20 17:50:43,654 WARNING Model Version creation error (name=churn_model) Retrying 2 more times.
[2025-08-20T17:50:45.943+0000] {subprocess.py:93} INFO - 2025-08-20 17:50:45,942 WARNING Model Version creation error (name=churn_model) Retrying 1 more time.
[2025-08-20T17:50:46.896+0000] {subprocess.py:93} INFO - 2025-08-20 17:50:46,895 WARNING Model Version creation error (name=churn_model) Retrying 0 more time.
[2025-08-20T17:50:47.068+0000] {subprocess.py:93} INFO - 2025-08-20 17:50:47,068 WARNING MLflow model registry logging failed: Model Version creation error (name=churn_model). Error: [Errno 1] Operation not permitted. Giving up after 3 attempts.. Continuing with local model only.
[2025-08-20T17:50:49.374+0000] {subprocess.py:97} INFO - Command exited with return code 0
[2025-08-20T17:50:49.574+0000] {taskinstance.py:1149} INFO - Marking task as SUCCESS. dag_id=customer_churn_pipeline, task_id=model_training, execution_date=20250819T000000, start_date=20250820T174921, end_date=20250820T175049
[2025-08-20T17:50:49.739+0000] {local_task_job_runner.py:234} INFO - Task exited with return code 0
[2025-08-20T17:50:49.921+0000] {taskinstance.py:3312} INFO - 1 downstream tasks scheduled from follow-on schedule check
