[2025-08-19T19:23:54.408+0000] {taskinstance.py:1979} INFO - Dependencies all met for dep_context=non-requeueable deps ti=<TaskInstance: customer_churn_pipeline.model_training manual__2025-08-19T19:22:42.304196+00:00 [queued]>
[2025-08-19T19:23:54.422+0000] {taskinstance.py:1979} INFO - Dependencies all met for dep_context=requeueable deps ti=<TaskInstance: customer_churn_pipeline.model_training manual__2025-08-19T19:22:42.304196+00:00 [queued]>
[2025-08-19T19:23:54.424+0000] {taskinstance.py:2193} INFO - Starting attempt 1 of 1
[2025-08-19T19:23:54.450+0000] {taskinstance.py:2217} INFO - Executing <Task(BashOperator): model_training> on 2025-08-19 19:22:42.304196+00:00
[2025-08-19T19:23:54.461+0000] {standard_task_runner.py:60} INFO - Started process 357 to run task
[2025-08-19T19:23:54.469+0000] {standard_task_runner.py:87} INFO - Running: ['***', 'tasks', 'run', 'customer_churn_pipeline', 'model_training', 'manual__2025-08-19T19:22:42.304196+00:00', '--job-id', '41', '--raw', '--subdir', 'DAGS_FOLDER/customer_churn_pipeline_dag.py', '--cfg-path', '/tmp/tmpuj5u_836']
[2025-08-19T19:23:54.475+0000] {standard_task_runner.py:88} INFO - Job 41: Subtask model_training
[2025-08-19T19:23:54.566+0000] {task_command.py:423} INFO - Running <TaskInstance: customer_churn_pipeline.model_training manual__2025-08-19T19:22:42.304196+00:00 [running]> on host dc08f7cf7bac
[2025-08-19T19:23:54.697+0000] {taskinstance.py:2513} INFO - Exporting env vars: AIRFLOW_CTX_DAG_OWNER='***' AIRFLOW_CTX_DAG_ID='customer_churn_pipeline' AIRFLOW_CTX_TASK_ID='model_training' AIRFLOW_CTX_EXECUTION_DATE='2025-08-19T19:22:42.304196+00:00' AIRFLOW_CTX_TRY_NUMBER='1' AIRFLOW_CTX_DAG_RUN_ID='manual__2025-08-19T19:22:42.304196+00:00'
[2025-08-19T19:23:54.699+0000] {subprocess.py:63} INFO - Tmp dir root location: /tmp
[2025-08-19T19:23:54.701+0000] {subprocess.py:75} INFO - Running command: ['/usr/bin/bash', '-c', 'cd /opt/***/Customer_Churn_Prediction_Pipeline && python src/train_model.py']
[2025-08-19T19:23:54.720+0000] {subprocess.py:86} INFO - Output:
[2025-08-19T19:24:00.523+0000] {subprocess.py:93} INFO - 2025-08-19 19:24:00,506 WARNING Malformed experiment '3c451db2cddf461b9fa24b573ecdc116'. Detailed error Yaml file '/opt/***/Customer_Churn_Prediction_Pipeline/mlruns/3c451db2cddf461b9fa24b573ecdc116/meta.yaml' does not exist.
[2025-08-19T19:24:00.525+0000] {subprocess.py:93} INFO - Traceback (most recent call last):
[2025-08-19T19:24:00.527+0000] {subprocess.py:93} INFO -   File "/home/***/.local/lib/python3.8/site-packages/mlflow/store/tracking/file_store.py", line 327, in search_experiments
[2025-08-19T19:24:00.528+0000] {subprocess.py:93} INFO -     exp = self._get_experiment(exp_id, view_type)
[2025-08-19T19:24:00.529+0000] {subprocess.py:93} INFO -   File "/home/***/.local/lib/python3.8/site-packages/mlflow/store/tracking/file_store.py", line 421, in _get_experiment
[2025-08-19T19:24:00.531+0000] {subprocess.py:93} INFO -     meta = FileStore._read_yaml(experiment_dir, FileStore.META_DATA_FILE_NAME)
[2025-08-19T19:24:00.532+0000] {subprocess.py:93} INFO -   File "/home/***/.local/lib/python3.8/site-packages/mlflow/store/tracking/file_store.py", line 1367, in _read_yaml
[2025-08-19T19:24:00.534+0000] {subprocess.py:93} INFO -     return _read_helper(root, file_name, attempts_remaining=retries)
[2025-08-19T19:24:00.535+0000] {subprocess.py:93} INFO -   File "/home/***/.local/lib/python3.8/site-packages/mlflow/store/tracking/file_store.py", line 1360, in _read_helper
[2025-08-19T19:24:00.536+0000] {subprocess.py:93} INFO -     result = read_yaml(root, file_name)
[2025-08-19T19:24:00.538+0000] {subprocess.py:93} INFO -   File "/home/***/.local/lib/python3.8/site-packages/mlflow/utils/file_utils.py", line 309, in read_yaml
[2025-08-19T19:24:00.539+0000] {subprocess.py:93} INFO -     raise MissingConfigException(f"Yaml file '{file_path}' does not exist.")
[2025-08-19T19:24:00.541+0000] {subprocess.py:93} INFO - mlflow.exceptions.MissingConfigException: Yaml file '/opt/***/Customer_Churn_Prediction_Pipeline/mlruns/3c451db2cddf461b9fa24b573ecdc116/meta.yaml' does not exist.
[2025-08-19T19:24:00.644+0000] {subprocess.py:93} INFO - 2025-08-19 19:24:00,643 WARNING Malformed experiment '66a6a96d2c6e463cbcf97c942dce679d'. Detailed error Yaml file '/opt/***/Customer_Churn_Prediction_Pipeline/mlruns/66a6a96d2c6e463cbcf97c942dce679d/meta.yaml' does not exist.
[2025-08-19T19:24:00.647+0000] {subprocess.py:93} INFO - Traceback (most recent call last):
[2025-08-19T19:24:00.663+0000] {subprocess.py:93} INFO -   File "/home/***/.local/lib/python3.8/site-packages/mlflow/store/tracking/file_store.py", line 327, in search_experiments
[2025-08-19T19:24:00.665+0000] {subprocess.py:93} INFO -     exp = self._get_experiment(exp_id, view_type)
[2025-08-19T19:24:00.681+0000] {subprocess.py:93} INFO -   File "/home/***/.local/lib/python3.8/site-packages/mlflow/store/tracking/file_store.py", line 421, in _get_experiment
[2025-08-19T19:24:00.683+0000] {subprocess.py:93} INFO -     meta = FileStore._read_yaml(experiment_dir, FileStore.META_DATA_FILE_NAME)
[2025-08-19T19:24:00.695+0000] {subprocess.py:93} INFO -   File "/home/***/.local/lib/python3.8/site-packages/mlflow/store/tracking/file_store.py", line 1367, in _read_yaml
[2025-08-19T19:24:00.698+0000] {subprocess.py:93} INFO -     return _read_helper(root, file_name, attempts_remaining=retries)
[2025-08-19T19:24:00.701+0000] {subprocess.py:93} INFO -   File "/home/***/.local/lib/python3.8/site-packages/mlflow/store/tracking/file_store.py", line 1360, in _read_helper
[2025-08-19T19:24:00.703+0000] {subprocess.py:93} INFO -     result = read_yaml(root, file_name)
[2025-08-19T19:24:00.705+0000] {subprocess.py:93} INFO -   File "/home/***/.local/lib/python3.8/site-packages/mlflow/utils/file_utils.py", line 309, in read_yaml
[2025-08-19T19:24:00.707+0000] {subprocess.py:93} INFO -     raise MissingConfigException(f"Yaml file '{file_path}' does not exist.")
[2025-08-19T19:24:00.708+0000] {subprocess.py:93} INFO - mlflow.exceptions.MissingConfigException: Yaml file '/opt/***/Customer_Churn_Prediction_Pipeline/mlruns/66a6a96d2c6e463cbcf97c942dce679d/meta.yaml' does not exist.
[2025-08-19T19:24:00.710+0000] {subprocess.py:93} INFO - 2025-08-19 19:24:00,705 WARNING Malformed experiment '758f77ef4c794795bdfdff4c02503bcc'. Detailed error Yaml file '/opt/***/Customer_Churn_Prediction_Pipeline/mlruns/758f77ef4c794795bdfdff4c02503bcc/meta.yaml' does not exist.
[2025-08-19T19:24:00.713+0000] {subprocess.py:93} INFO - Traceback (most recent call last):
[2025-08-19T19:24:00.715+0000] {subprocess.py:93} INFO -   File "/home/***/.local/lib/python3.8/site-packages/mlflow/store/tracking/file_store.py", line 327, in search_experiments
[2025-08-19T19:24:00.716+0000] {subprocess.py:93} INFO -     exp = self._get_experiment(exp_id, view_type)
[2025-08-19T19:24:00.717+0000] {subprocess.py:93} INFO -   File "/home/***/.local/lib/python3.8/site-packages/mlflow/store/tracking/file_store.py", line 421, in _get_experiment
[2025-08-19T19:24:00.719+0000] {subprocess.py:93} INFO -     meta = FileStore._read_yaml(experiment_dir, FileStore.META_DATA_FILE_NAME)
[2025-08-19T19:24:00.720+0000] {subprocess.py:93} INFO -   File "/home/***/.local/lib/python3.8/site-packages/mlflow/store/tracking/file_store.py", line 1367, in _read_yaml
[2025-08-19T19:24:00.721+0000] {subprocess.py:93} INFO -     return _read_helper(root, file_name, attempts_remaining=retries)
[2025-08-19T19:24:00.723+0000] {subprocess.py:93} INFO -   File "/home/***/.local/lib/python3.8/site-packages/mlflow/store/tracking/file_store.py", line 1360, in _read_helper
[2025-08-19T19:24:00.724+0000] {subprocess.py:93} INFO -     result = read_yaml(root, file_name)
[2025-08-19T19:24:00.725+0000] {subprocess.py:93} INFO -   File "/home/***/.local/lib/python3.8/site-packages/mlflow/utils/file_utils.py", line 309, in read_yaml
[2025-08-19T19:24:00.726+0000] {subprocess.py:93} INFO -     raise MissingConfigException(f"Yaml file '{file_path}' does not exist.")
[2025-08-19T19:24:00.727+0000] {subprocess.py:93} INFO - mlflow.exceptions.MissingConfigException: Yaml file '/opt/***/Customer_Churn_Prediction_Pipeline/mlruns/758f77ef4c794795bdfdff4c02503bcc/meta.yaml' does not exist.
[2025-08-19T19:24:00.729+0000] {subprocess.py:93} INFO - 2025-08-19 19:24:00,721 WARNING Malformed experiment '7a4c300b24d14505ba7f4df32748abf9'. Detailed error Yaml file '/opt/***/Customer_Churn_Prediction_Pipeline/mlruns/7a4c300b24d14505ba7f4df32748abf9/meta.yaml' does not exist.
[2025-08-19T19:24:00.730+0000] {subprocess.py:93} INFO - Traceback (most recent call last):
[2025-08-19T19:24:00.732+0000] {subprocess.py:93} INFO -   File "/home/***/.local/lib/python3.8/site-packages/mlflow/store/tracking/file_store.py", line 327, in search_experiments
[2025-08-19T19:24:00.733+0000] {subprocess.py:93} INFO -     exp = self._get_experiment(exp_id, view_type)
[2025-08-19T19:24:00.734+0000] {subprocess.py:93} INFO -   File "/home/***/.local/lib/python3.8/site-packages/mlflow/store/tracking/file_store.py", line 421, in _get_experiment
[2025-08-19T19:24:00.736+0000] {subprocess.py:93} INFO -     meta = FileStore._read_yaml(experiment_dir, FileStore.META_DATA_FILE_NAME)
[2025-08-19T19:24:00.737+0000] {subprocess.py:93} INFO -   File "/home/***/.local/lib/python3.8/site-packages/mlflow/store/tracking/file_store.py", line 1367, in _read_yaml
[2025-08-19T19:24:00.738+0000] {subprocess.py:93} INFO -     return _read_helper(root, file_name, attempts_remaining=retries)
[2025-08-19T19:24:00.739+0000] {subprocess.py:93} INFO -   File "/home/***/.local/lib/python3.8/site-packages/mlflow/store/tracking/file_store.py", line 1360, in _read_helper
[2025-08-19T19:24:00.740+0000] {subprocess.py:93} INFO -     result = read_yaml(root, file_name)
[2025-08-19T19:24:00.741+0000] {subprocess.py:93} INFO -   File "/home/***/.local/lib/python3.8/site-packages/mlflow/utils/file_utils.py", line 309, in read_yaml
[2025-08-19T19:24:00.743+0000] {subprocess.py:93} INFO -     raise MissingConfigException(f"Yaml file '{file_path}' does not exist.")
[2025-08-19T19:24:00.744+0000] {subprocess.py:93} INFO - mlflow.exceptions.MissingConfigException: Yaml file '/opt/***/Customer_Churn_Prediction_Pipeline/mlruns/7a4c300b24d14505ba7f4df32748abf9/meta.yaml' does not exist.
[2025-08-19T19:24:00.745+0000] {subprocess.py:93} INFO - 2025-08-19 19:24:00,733 WARNING Malformed experiment '9f8a2292aea24d39a6b035889d38fb72'. Detailed error Yaml file '/opt/***/Customer_Churn_Prediction_Pipeline/mlruns/9f8a2292aea24d39a6b035889d38fb72/meta.yaml' does not exist.
[2025-08-19T19:24:00.746+0000] {subprocess.py:93} INFO - Traceback (most recent call last):
[2025-08-19T19:24:00.747+0000] {subprocess.py:93} INFO -   File "/home/***/.local/lib/python3.8/site-packages/mlflow/store/tracking/file_store.py", line 327, in search_experiments
[2025-08-19T19:24:00.748+0000] {subprocess.py:93} INFO -     exp = self._get_experiment(exp_id, view_type)
[2025-08-19T19:24:00.749+0000] {subprocess.py:93} INFO -   File "/home/***/.local/lib/python3.8/site-packages/mlflow/store/tracking/file_store.py", line 421, in _get_experiment
[2025-08-19T19:24:00.751+0000] {subprocess.py:93} INFO -     meta = FileStore._read_yaml(experiment_dir, FileStore.META_DATA_FILE_NAME)
[2025-08-19T19:24:00.752+0000] {subprocess.py:93} INFO -   File "/home/***/.local/lib/python3.8/site-packages/mlflow/store/tracking/file_store.py", line 1367, in _read_yaml
[2025-08-19T19:24:00.754+0000] {subprocess.py:93} INFO -     return _read_helper(root, file_name, attempts_remaining=retries)
[2025-08-19T19:24:00.755+0000] {subprocess.py:93} INFO -   File "/home/***/.local/lib/python3.8/site-packages/mlflow/store/tracking/file_store.py", line 1360, in _read_helper
[2025-08-19T19:24:00.756+0000] {subprocess.py:93} INFO -     result = read_yaml(root, file_name)
[2025-08-19T19:24:00.757+0000] {subprocess.py:93} INFO -   File "/home/***/.local/lib/python3.8/site-packages/mlflow/utils/file_utils.py", line 309, in read_yaml
[2025-08-19T19:24:00.759+0000] {subprocess.py:93} INFO -     raise MissingConfigException(f"Yaml file '{file_path}' does not exist.")
[2025-08-19T19:24:00.760+0000] {subprocess.py:93} INFO - mlflow.exceptions.MissingConfigException: Yaml file '/opt/***/Customer_Churn_Prediction_Pipeline/mlruns/9f8a2292aea24d39a6b035889d38fb72/meta.yaml' does not exist.
[2025-08-19T19:24:00.761+0000] {subprocess.py:93} INFO - 2025-08-19 19:24:00,744 WARNING Malformed experiment 'a20986ad69c34568ab9b4cdb0a0c41f5'. Detailed error Yaml file '/opt/***/Customer_Churn_Prediction_Pipeline/mlruns/a20986ad69c34568ab9b4cdb0a0c41f5/meta.yaml' does not exist.
[2025-08-19T19:24:00.762+0000] {subprocess.py:93} INFO - Traceback (most recent call last):
[2025-08-19T19:24:00.763+0000] {subprocess.py:93} INFO -   File "/home/***/.local/lib/python3.8/site-packages/mlflow/store/tracking/file_store.py", line 327, in search_experiments
[2025-08-19T19:24:00.764+0000] {subprocess.py:93} INFO -     exp = self._get_experiment(exp_id, view_type)
[2025-08-19T19:24:00.765+0000] {subprocess.py:93} INFO -   File "/home/***/.local/lib/python3.8/site-packages/mlflow/store/tracking/file_store.py", line 421, in _get_experiment
[2025-08-19T19:24:00.767+0000] {subprocess.py:93} INFO -     meta = FileStore._read_yaml(experiment_dir, FileStore.META_DATA_FILE_NAME)
[2025-08-19T19:24:00.769+0000] {subprocess.py:93} INFO -   File "/home/***/.local/lib/python3.8/site-packages/mlflow/store/tracking/file_store.py", line 1367, in _read_yaml
[2025-08-19T19:24:00.770+0000] {subprocess.py:93} INFO -     return _read_helper(root, file_name, attempts_remaining=retries)
[2025-08-19T19:24:00.771+0000] {subprocess.py:93} INFO -   File "/home/***/.local/lib/python3.8/site-packages/mlflow/store/tracking/file_store.py", line 1360, in _read_helper
[2025-08-19T19:24:00.771+0000] {subprocess.py:93} INFO -     result = read_yaml(root, file_name)
[2025-08-19T19:24:00.772+0000] {subprocess.py:93} INFO -   File "/home/***/.local/lib/python3.8/site-packages/mlflow/utils/file_utils.py", line 309, in read_yaml
[2025-08-19T19:24:00.774+0000] {subprocess.py:93} INFO -     raise MissingConfigException(f"Yaml file '{file_path}' does not exist.")
[2025-08-19T19:24:00.775+0000] {subprocess.py:93} INFO - mlflow.exceptions.MissingConfigException: Yaml file '/opt/***/Customer_Churn_Prediction_Pipeline/mlruns/a20986ad69c34568ab9b4cdb0a0c41f5/meta.yaml' does not exist.
[2025-08-19T19:24:00.776+0000] {subprocess.py:93} INFO - 2025-08-19 19:24:00,756 WARNING Malformed experiment 'b682dba240844ed68344d97d245b4459'. Detailed error Yaml file '/opt/***/Customer_Churn_Prediction_Pipeline/mlruns/b682dba240844ed68344d97d245b4459/meta.yaml' does not exist.
[2025-08-19T19:24:00.777+0000] {subprocess.py:93} INFO - Traceback (most recent call last):
[2025-08-19T19:24:00.778+0000] {subprocess.py:93} INFO -   File "/home/***/.local/lib/python3.8/site-packages/mlflow/store/tracking/file_store.py", line 327, in search_experiments
[2025-08-19T19:24:00.779+0000] {subprocess.py:93} INFO -     exp = self._get_experiment(exp_id, view_type)
[2025-08-19T19:24:00.781+0000] {subprocess.py:93} INFO -   File "/home/***/.local/lib/python3.8/site-packages/mlflow/store/tracking/file_store.py", line 421, in _get_experiment
[2025-08-19T19:24:00.782+0000] {subprocess.py:93} INFO -     meta = FileStore._read_yaml(experiment_dir, FileStore.META_DATA_FILE_NAME)
[2025-08-19T19:24:00.783+0000] {subprocess.py:93} INFO -   File "/home/***/.local/lib/python3.8/site-packages/mlflow/store/tracking/file_store.py", line 1367, in _read_yaml
[2025-08-19T19:24:00.785+0000] {subprocess.py:93} INFO -     return _read_helper(root, file_name, attempts_remaining=retries)
[2025-08-19T19:24:00.786+0000] {subprocess.py:93} INFO -   File "/home/***/.local/lib/python3.8/site-packages/mlflow/store/tracking/file_store.py", line 1360, in _read_helper
[2025-08-19T19:24:00.788+0000] {subprocess.py:93} INFO -     result = read_yaml(root, file_name)
[2025-08-19T19:24:00.790+0000] {subprocess.py:93} INFO -   File "/home/***/.local/lib/python3.8/site-packages/mlflow/utils/file_utils.py", line 309, in read_yaml
[2025-08-19T19:24:00.793+0000] {subprocess.py:93} INFO -     raise MissingConfigException(f"Yaml file '{file_path}' does not exist.")
[2025-08-19T19:24:00.795+0000] {subprocess.py:93} INFO - mlflow.exceptions.MissingConfigException: Yaml file '/opt/***/Customer_Churn_Prediction_Pipeline/mlruns/b682dba240844ed68344d97d245b4459/meta.yaml' does not exist.
[2025-08-19T19:24:00.800+0000] {subprocess.py:93} INFO - 2025-08-19 19:24:00,767 WARNING Malformed experiment 'e45a2c3f2fe5435bb5ee5c51f9930955'. Detailed error Yaml file '/opt/***/Customer_Churn_Prediction_Pipeline/mlruns/e45a2c3f2fe5435bb5ee5c51f9930955/meta.yaml' does not exist.
[2025-08-19T19:24:00.802+0000] {subprocess.py:93} INFO - Traceback (most recent call last):
[2025-08-19T19:24:00.803+0000] {subprocess.py:93} INFO -   File "/home/***/.local/lib/python3.8/site-packages/mlflow/store/tracking/file_store.py", line 327, in search_experiments
[2025-08-19T19:24:00.804+0000] {subprocess.py:93} INFO -     exp = self._get_experiment(exp_id, view_type)
[2025-08-19T19:24:00.805+0000] {subprocess.py:93} INFO -   File "/home/***/.local/lib/python3.8/site-packages/mlflow/store/tracking/file_store.py", line 421, in _get_experiment
[2025-08-19T19:24:00.807+0000] {subprocess.py:93} INFO -     meta = FileStore._read_yaml(experiment_dir, FileStore.META_DATA_FILE_NAME)
[2025-08-19T19:24:00.808+0000] {subprocess.py:93} INFO -   File "/home/***/.local/lib/python3.8/site-packages/mlflow/store/tracking/file_store.py", line 1367, in _read_yaml
[2025-08-19T19:24:00.809+0000] {subprocess.py:93} INFO -     return _read_helper(root, file_name, attempts_remaining=retries)
[2025-08-19T19:24:00.810+0000] {subprocess.py:93} INFO -   File "/home/***/.local/lib/python3.8/site-packages/mlflow/store/tracking/file_store.py", line 1360, in _read_helper
[2025-08-19T19:24:00.812+0000] {subprocess.py:93} INFO -     result = read_yaml(root, file_name)
[2025-08-19T19:24:00.813+0000] {subprocess.py:93} INFO -   File "/home/***/.local/lib/python3.8/site-packages/mlflow/utils/file_utils.py", line 309, in read_yaml
[2025-08-19T19:24:00.814+0000] {subprocess.py:93} INFO -     raise MissingConfigException(f"Yaml file '{file_path}' does not exist.")
[2025-08-19T19:24:00.816+0000] {subprocess.py:93} INFO - mlflow.exceptions.MissingConfigException: Yaml file '/opt/***/Customer_Churn_Prediction_Pipeline/mlruns/e45a2c3f2fe5435bb5ee5c51f9930955/meta.yaml' does not exist.
[2025-08-19T19:24:00.877+0000] {subprocess.py:93} INFO - 2025-08-19 19:24:00,876 WARNING Malformed experiment '3c451db2cddf461b9fa24b573ecdc116'. Detailed error Yaml file '/opt/***/Customer_Churn_Prediction_Pipeline/mlruns/3c451db2cddf461b9fa24b573ecdc116/meta.yaml' does not exist.
[2025-08-19T19:24:00.879+0000] {subprocess.py:93} INFO - Traceback (most recent call last):
[2025-08-19T19:24:00.880+0000] {subprocess.py:93} INFO -   File "/home/***/.local/lib/python3.8/site-packages/mlflow/store/tracking/file_store.py", line 327, in search_experiments
[2025-08-19T19:24:00.881+0000] {subprocess.py:93} INFO -     exp = self._get_experiment(exp_id, view_type)
[2025-08-19T19:24:00.882+0000] {subprocess.py:93} INFO -   File "/home/***/.local/lib/python3.8/site-packages/mlflow/store/tracking/file_store.py", line 421, in _get_experiment
[2025-08-19T19:24:00.883+0000] {subprocess.py:93} INFO -     meta = FileStore._read_yaml(experiment_dir, FileStore.META_DATA_FILE_NAME)
[2025-08-19T19:24:00.885+0000] {subprocess.py:93} INFO -   File "/home/***/.local/lib/python3.8/site-packages/mlflow/store/tracking/file_store.py", line 1367, in _read_yaml
[2025-08-19T19:24:00.886+0000] {subprocess.py:93} INFO -     return _read_helper(root, file_name, attempts_remaining=retries)
[2025-08-19T19:24:00.887+0000] {subprocess.py:93} INFO -   File "/home/***/.local/lib/python3.8/site-packages/mlflow/store/tracking/file_store.py", line 1360, in _read_helper
[2025-08-19T19:24:00.888+0000] {subprocess.py:93} INFO -     result = read_yaml(root, file_name)
[2025-08-19T19:24:00.889+0000] {subprocess.py:93} INFO -   File "/home/***/.local/lib/python3.8/site-packages/mlflow/utils/file_utils.py", line 309, in read_yaml
[2025-08-19T19:24:00.890+0000] {subprocess.py:93} INFO -     raise MissingConfigException(f"Yaml file '{file_path}' does not exist.")
[2025-08-19T19:24:00.891+0000] {subprocess.py:93} INFO - mlflow.exceptions.MissingConfigException: Yaml file '/opt/***/Customer_Churn_Prediction_Pipeline/mlruns/3c451db2cddf461b9fa24b573ecdc116/meta.yaml' does not exist.
[2025-08-19T19:24:00.941+0000] {subprocess.py:93} INFO - 2025-08-19 19:24:00,940 WARNING Malformed experiment '66a6a96d2c6e463cbcf97c942dce679d'. Detailed error Yaml file '/opt/***/Customer_Churn_Prediction_Pipeline/mlruns/66a6a96d2c6e463cbcf97c942dce679d/meta.yaml' does not exist.
[2025-08-19T19:24:00.942+0000] {subprocess.py:93} INFO - Traceback (most recent call last):
[2025-08-19T19:24:00.943+0000] {subprocess.py:93} INFO -   File "/home/***/.local/lib/python3.8/site-packages/mlflow/store/tracking/file_store.py", line 327, in search_experiments
[2025-08-19T19:24:00.944+0000] {subprocess.py:93} INFO -     exp = self._get_experiment(exp_id, view_type)
[2025-08-19T19:24:00.945+0000] {subprocess.py:93} INFO -   File "/home/***/.local/lib/python3.8/site-packages/mlflow/store/tracking/file_store.py", line 421, in _get_experiment
[2025-08-19T19:24:00.946+0000] {subprocess.py:93} INFO -     meta = FileStore._read_yaml(experiment_dir, FileStore.META_DATA_FILE_NAME)
[2025-08-19T19:24:00.947+0000] {subprocess.py:93} INFO -   File "/home/***/.local/lib/python3.8/site-packages/mlflow/store/tracking/file_store.py", line 1367, in _read_yaml
[2025-08-19T19:24:00.948+0000] {subprocess.py:93} INFO -     return _read_helper(root, file_name, attempts_remaining=retries)
[2025-08-19T19:24:00.949+0000] {subprocess.py:93} INFO -   File "/home/***/.local/lib/python3.8/site-packages/mlflow/store/tracking/file_store.py", line 1360, in _read_helper
[2025-08-19T19:24:00.951+0000] {subprocess.py:93} INFO -     result = read_yaml(root, file_name)
[2025-08-19T19:24:00.952+0000] {subprocess.py:93} INFO -   File "/home/***/.local/lib/python3.8/site-packages/mlflow/utils/file_utils.py", line 309, in read_yaml
[2025-08-19T19:24:00.955+0000] {subprocess.py:93} INFO -     raise MissingConfigException(f"Yaml file '{file_path}' does not exist.")
[2025-08-19T19:24:00.958+0000] {subprocess.py:93} INFO - mlflow.exceptions.MissingConfigException: Yaml file '/opt/***/Customer_Churn_Prediction_Pipeline/mlruns/66a6a96d2c6e463cbcf97c942dce679d/meta.yaml' does not exist.
[2025-08-19T19:24:00.960+0000] {subprocess.py:93} INFO - 2025-08-19 19:24:00,953 WARNING Malformed experiment '758f77ef4c794795bdfdff4c02503bcc'. Detailed error Yaml file '/opt/***/Customer_Churn_Prediction_Pipeline/mlruns/758f77ef4c794795bdfdff4c02503bcc/meta.yaml' does not exist.
[2025-08-19T19:24:00.963+0000] {subprocess.py:93} INFO - Traceback (most recent call last):
[2025-08-19T19:24:00.964+0000] {subprocess.py:93} INFO -   File "/home/***/.local/lib/python3.8/site-packages/mlflow/store/tracking/file_store.py", line 327, in search_experiments
[2025-08-19T19:24:00.965+0000] {subprocess.py:93} INFO -     exp = self._get_experiment(exp_id, view_type)
[2025-08-19T19:24:00.967+0000] {subprocess.py:93} INFO -   File "/home/***/.local/lib/python3.8/site-packages/mlflow/store/tracking/file_store.py", line 421, in _get_experiment
[2025-08-19T19:24:00.969+0000] {subprocess.py:93} INFO -     meta = FileStore._read_yaml(experiment_dir, FileStore.META_DATA_FILE_NAME)
[2025-08-19T19:24:00.970+0000] {subprocess.py:93} INFO -   File "/home/***/.local/lib/python3.8/site-packages/mlflow/store/tracking/file_store.py", line 1367, in _read_yaml
[2025-08-19T19:24:00.972+0000] {subprocess.py:93} INFO -     return _read_helper(root, file_name, attempts_remaining=retries)
[2025-08-19T19:24:00.973+0000] {subprocess.py:93} INFO -   File "/home/***/.local/lib/python3.8/site-packages/mlflow/store/tracking/file_store.py", line 1360, in _read_helper
[2025-08-19T19:24:00.974+0000] {subprocess.py:93} INFO -     result = read_yaml(root, file_name)
[2025-08-19T19:24:00.975+0000] {subprocess.py:93} INFO -   File "/home/***/.local/lib/python3.8/site-packages/mlflow/utils/file_utils.py", line 309, in read_yaml
[2025-08-19T19:24:00.976+0000] {subprocess.py:93} INFO -     raise MissingConfigException(f"Yaml file '{file_path}' does not exist.")
[2025-08-19T19:24:00.977+0000] {subprocess.py:93} INFO - mlflow.exceptions.MissingConfigException: Yaml file '/opt/***/Customer_Churn_Prediction_Pipeline/mlruns/758f77ef4c794795bdfdff4c02503bcc/meta.yaml' does not exist.
[2025-08-19T19:24:00.978+0000] {subprocess.py:93} INFO - 2025-08-19 19:24:00,970 WARNING Malformed experiment '7a4c300b24d14505ba7f4df32748abf9'. Detailed error Yaml file '/opt/***/Customer_Churn_Prediction_Pipeline/mlruns/7a4c300b24d14505ba7f4df32748abf9/meta.yaml' does not exist.
[2025-08-19T19:24:00.980+0000] {subprocess.py:93} INFO - Traceback (most recent call last):
[2025-08-19T19:24:00.981+0000] {subprocess.py:93} INFO -   File "/home/***/.local/lib/python3.8/site-packages/mlflow/store/tracking/file_store.py", line 327, in search_experiments
[2025-08-19T19:24:00.982+0000] {subprocess.py:93} INFO -     exp = self._get_experiment(exp_id, view_type)
[2025-08-19T19:24:00.983+0000] {subprocess.py:93} INFO -   File "/home/***/.local/lib/python3.8/site-packages/mlflow/store/tracking/file_store.py", line 421, in _get_experiment
[2025-08-19T19:24:00.984+0000] {subprocess.py:93} INFO -     meta = FileStore._read_yaml(experiment_dir, FileStore.META_DATA_FILE_NAME)
[2025-08-19T19:24:00.985+0000] {subprocess.py:93} INFO -   File "/home/***/.local/lib/python3.8/site-packages/mlflow/store/tracking/file_store.py", line 1367, in _read_yaml
[2025-08-19T19:24:00.987+0000] {subprocess.py:93} INFO -     return _read_helper(root, file_name, attempts_remaining=retries)
[2025-08-19T19:24:00.988+0000] {subprocess.py:93} INFO -   File "/home/***/.local/lib/python3.8/site-packages/mlflow/store/tracking/file_store.py", line 1360, in _read_helper
[2025-08-19T19:24:00.989+0000] {subprocess.py:93} INFO -     result = read_yaml(root, file_name)
[2025-08-19T19:24:00.990+0000] {subprocess.py:93} INFO -   File "/home/***/.local/lib/python3.8/site-packages/mlflow/utils/file_utils.py", line 309, in read_yaml
[2025-08-19T19:24:00.992+0000] {subprocess.py:93} INFO -     raise MissingConfigException(f"Yaml file '{file_path}' does not exist.")
[2025-08-19T19:24:00.993+0000] {subprocess.py:93} INFO - mlflow.exceptions.MissingConfigException: Yaml file '/opt/***/Customer_Churn_Prediction_Pipeline/mlruns/7a4c300b24d14505ba7f4df32748abf9/meta.yaml' does not exist.
[2025-08-19T19:24:00.994+0000] {subprocess.py:93} INFO - 2025-08-19 19:24:00,982 WARNING Malformed experiment '9f8a2292aea24d39a6b035889d38fb72'. Detailed error Yaml file '/opt/***/Customer_Churn_Prediction_Pipeline/mlruns/9f8a2292aea24d39a6b035889d38fb72/meta.yaml' does not exist.
[2025-08-19T19:24:00.995+0000] {subprocess.py:93} INFO - Traceback (most recent call last):
[2025-08-19T19:24:00.997+0000] {subprocess.py:93} INFO -   File "/home/***/.local/lib/python3.8/site-packages/mlflow/store/tracking/file_store.py", line 327, in search_experiments
[2025-08-19T19:24:00.998+0000] {subprocess.py:93} INFO -     exp = self._get_experiment(exp_id, view_type)
[2025-08-19T19:24:00.999+0000] {subprocess.py:93} INFO -   File "/home/***/.local/lib/python3.8/site-packages/mlflow/store/tracking/file_store.py", line 421, in _get_experiment
[2025-08-19T19:24:01.001+0000] {subprocess.py:93} INFO -     meta = FileStore._read_yaml(experiment_dir, FileStore.META_DATA_FILE_NAME)
[2025-08-19T19:24:01.002+0000] {subprocess.py:93} INFO -   File "/home/***/.local/lib/python3.8/site-packages/mlflow/store/tracking/file_store.py", line 1367, in _read_yaml
[2025-08-19T19:24:01.003+0000] {subprocess.py:93} INFO -     return _read_helper(root, file_name, attempts_remaining=retries)
[2025-08-19T19:24:01.005+0000] {subprocess.py:93} INFO -   File "/home/***/.local/lib/python3.8/site-packages/mlflow/store/tracking/file_store.py", line 1360, in _read_helper
[2025-08-19T19:24:01.006+0000] {subprocess.py:93} INFO -     result = read_yaml(root, file_name)
[2025-08-19T19:24:01.007+0000] {subprocess.py:93} INFO -   File "/home/***/.local/lib/python3.8/site-packages/mlflow/utils/file_utils.py", line 309, in read_yaml
[2025-08-19T19:24:01.008+0000] {subprocess.py:93} INFO -     raise MissingConfigException(f"Yaml file '{file_path}' does not exist.")
[2025-08-19T19:24:01.009+0000] {subprocess.py:93} INFO - mlflow.exceptions.MissingConfigException: Yaml file '/opt/***/Customer_Churn_Prediction_Pipeline/mlruns/9f8a2292aea24d39a6b035889d38fb72/meta.yaml' does not exist.
[2025-08-19T19:24:01.010+0000] {subprocess.py:93} INFO - 2025-08-19 19:24:00,994 WARNING Malformed experiment 'a20986ad69c34568ab9b4cdb0a0c41f5'. Detailed error Yaml file '/opt/***/Customer_Churn_Prediction_Pipeline/mlruns/a20986ad69c34568ab9b4cdb0a0c41f5/meta.yaml' does not exist.
[2025-08-19T19:24:01.012+0000] {subprocess.py:93} INFO - Traceback (most recent call last):
[2025-08-19T19:24:01.013+0000] {subprocess.py:93} INFO -   File "/home/***/.local/lib/python3.8/site-packages/mlflow/store/tracking/file_store.py", line 327, in search_experiments
[2025-08-19T19:24:01.014+0000] {subprocess.py:93} INFO -     exp = self._get_experiment(exp_id, view_type)
[2025-08-19T19:24:01.015+0000] {subprocess.py:93} INFO -   File "/home/***/.local/lib/python3.8/site-packages/mlflow/store/tracking/file_store.py", line 421, in _get_experiment
[2025-08-19T19:24:01.016+0000] {subprocess.py:93} INFO -     meta = FileStore._read_yaml(experiment_dir, FileStore.META_DATA_FILE_NAME)
[2025-08-19T19:24:01.017+0000] {subprocess.py:93} INFO -   File "/home/***/.local/lib/python3.8/site-packages/mlflow/store/tracking/file_store.py", line 1367, in _read_yaml
[2025-08-19T19:24:01.019+0000] {subprocess.py:93} INFO -     return _read_helper(root, file_name, attempts_remaining=retries)
[2025-08-19T19:24:01.019+0000] {subprocess.py:93} INFO -   File "/home/***/.local/lib/python3.8/site-packages/mlflow/store/tracking/file_store.py", line 1360, in _read_helper
[2025-08-19T19:24:01.021+0000] {subprocess.py:93} INFO -     result = read_yaml(root, file_name)
[2025-08-19T19:24:01.022+0000] {subprocess.py:93} INFO -   File "/home/***/.local/lib/python3.8/site-packages/mlflow/utils/file_utils.py", line 309, in read_yaml
[2025-08-19T19:24:01.023+0000] {subprocess.py:93} INFO -     raise MissingConfigException(f"Yaml file '{file_path}' does not exist.")
[2025-08-19T19:24:01.024+0000] {subprocess.py:93} INFO - mlflow.exceptions.MissingConfigException: Yaml file '/opt/***/Customer_Churn_Prediction_Pipeline/mlruns/a20986ad69c34568ab9b4cdb0a0c41f5/meta.yaml' does not exist.
[2025-08-19T19:24:01.025+0000] {subprocess.py:93} INFO - 2025-08-19 19:24:01,006 WARNING Malformed experiment 'b682dba240844ed68344d97d245b4459'. Detailed error Yaml file '/opt/***/Customer_Churn_Prediction_Pipeline/mlruns/b682dba240844ed68344d97d245b4459/meta.yaml' does not exist.
[2025-08-19T19:24:01.026+0000] {subprocess.py:93} INFO - Traceback (most recent call last):
[2025-08-19T19:24:01.028+0000] {subprocess.py:93} INFO -   File "/home/***/.local/lib/python3.8/site-packages/mlflow/store/tracking/file_store.py", line 327, in search_experiments
[2025-08-19T19:24:01.029+0000] {subprocess.py:93} INFO -     exp = self._get_experiment(exp_id, view_type)
[2025-08-19T19:24:01.030+0000] {subprocess.py:93} INFO -   File "/home/***/.local/lib/python3.8/site-packages/mlflow/store/tracking/file_store.py", line 421, in _get_experiment
[2025-08-19T19:24:01.031+0000] {subprocess.py:93} INFO -     meta = FileStore._read_yaml(experiment_dir, FileStore.META_DATA_FILE_NAME)
[2025-08-19T19:24:01.032+0000] {subprocess.py:93} INFO -   File "/home/***/.local/lib/python3.8/site-packages/mlflow/store/tracking/file_store.py", line 1367, in _read_yaml
[2025-08-19T19:24:01.033+0000] {subprocess.py:93} INFO -     return _read_helper(root, file_name, attempts_remaining=retries)
[2025-08-19T19:24:01.034+0000] {subprocess.py:93} INFO -   File "/home/***/.local/lib/python3.8/site-packages/mlflow/store/tracking/file_store.py", line 1360, in _read_helper
[2025-08-19T19:24:01.035+0000] {subprocess.py:93} INFO -     result = read_yaml(root, file_name)
[2025-08-19T19:24:01.036+0000] {subprocess.py:93} INFO -   File "/home/***/.local/lib/python3.8/site-packages/mlflow/utils/file_utils.py", line 309, in read_yaml
[2025-08-19T19:24:01.037+0000] {subprocess.py:93} INFO -     raise MissingConfigException(f"Yaml file '{file_path}' does not exist.")
[2025-08-19T19:24:01.039+0000] {subprocess.py:93} INFO - mlflow.exceptions.MissingConfigException: Yaml file '/opt/***/Customer_Churn_Prediction_Pipeline/mlruns/b682dba240844ed68344d97d245b4459/meta.yaml' does not exist.
[2025-08-19T19:24:01.041+0000] {subprocess.py:93} INFO - 2025-08-19 19:24:01,017 WARNING Malformed experiment 'e45a2c3f2fe5435bb5ee5c51f9930955'. Detailed error Yaml file '/opt/***/Customer_Churn_Prediction_Pipeline/mlruns/e45a2c3f2fe5435bb5ee5c51f9930955/meta.yaml' does not exist.
[2025-08-19T19:24:01.043+0000] {subprocess.py:93} INFO - Traceback (most recent call last):
[2025-08-19T19:24:01.044+0000] {subprocess.py:93} INFO -   File "/home/***/.local/lib/python3.8/site-packages/mlflow/store/tracking/file_store.py", line 327, in search_experiments
[2025-08-19T19:24:01.045+0000] {subprocess.py:93} INFO -     exp = self._get_experiment(exp_id, view_type)
[2025-08-19T19:24:01.046+0000] {subprocess.py:93} INFO -   File "/home/***/.local/lib/python3.8/site-packages/mlflow/store/tracking/file_store.py", line 421, in _get_experiment
[2025-08-19T19:24:01.047+0000] {subprocess.py:93} INFO -     meta = FileStore._read_yaml(experiment_dir, FileStore.META_DATA_FILE_NAME)
[2025-08-19T19:24:01.048+0000] {subprocess.py:93} INFO -   File "/home/***/.local/lib/python3.8/site-packages/mlflow/store/tracking/file_store.py", line 1367, in _read_yaml
[2025-08-19T19:24:01.049+0000] {subprocess.py:93} INFO -     return _read_helper(root, file_name, attempts_remaining=retries)
[2025-08-19T19:24:01.050+0000] {subprocess.py:93} INFO -   File "/home/***/.local/lib/python3.8/site-packages/mlflow/store/tracking/file_store.py", line 1360, in _read_helper
[2025-08-19T19:24:01.051+0000] {subprocess.py:93} INFO -     result = read_yaml(root, file_name)
[2025-08-19T19:24:01.052+0000] {subprocess.py:93} INFO -   File "/home/***/.local/lib/python3.8/site-packages/mlflow/utils/file_utils.py", line 309, in read_yaml
[2025-08-19T19:24:01.054+0000] {subprocess.py:93} INFO -     raise MissingConfigException(f"Yaml file '{file_path}' does not exist.")
[2025-08-19T19:24:01.055+0000] {subprocess.py:93} INFO - mlflow.exceptions.MissingConfigException: Yaml file '/opt/***/Customer_Churn_Prediction_Pipeline/mlruns/e45a2c3f2fe5435bb5ee5c51f9930955/meta.yaml' does not exist.
[2025-08-19T19:24:01.057+0000] {subprocess.py:93} INFO - 2025-08-19 19:24:01,020 INFO Loading features and target from feature store...
[2025-08-19T19:24:01.058+0000] {subprocess.py:93} INFO - 2025-08-19 19:24:01,020 INFO Connecting to SQLite DB at data/features/churn_features.db
[2025-08-19T19:24:01.060+0000] {subprocess.py:93} INFO - 2025-08-19 19:24:01,039 INFO Available tables: ['churn_features']
[2025-08-19T19:24:01.761+0000] {subprocess.py:93} INFO - 2025-08-19 19:24:01,759 INFO Retrieved 7032 rows and 36 columns from table churn_features
[2025-08-19T19:24:01.764+0000] {subprocess.py:93} INFO - 2025-08-19 19:24:01,763 INFO Found target column 'Churn'. Processing...
[2025-08-19T19:24:01.765+0000] {subprocess.py:93} INFO - 2025-08-19 19:24:01,763 INFO Raw target column stats:
[2025-08-19T19:24:01.768+0000] {subprocess.py:93} INFO - 2025-08-19 19:24:01,763 INFO   - Type: float64
[2025-08-19T19:24:01.769+0000] {subprocess.py:93} INFO - 2025-08-19 19:24:01,764 INFO   - Unique values: [-0.601663392508594, 1.6620589061112205]
[2025-08-19T19:24:01.770+0000] {subprocess.py:93} INFO - 2025-08-19 19:24:01,768 INFO   - Value counts:
[2025-08-19T19:24:01.773+0000] {subprocess.py:93} INFO - -0.601663    5163
[2025-08-19T19:24:01.774+0000] {subprocess.py:93} INFO -  1.662059    1869
[2025-08-19T19:24:01.775+0000] {subprocess.py:93} INFO - Name: Churn, dtype: int64
[2025-08-19T19:24:01.778+0000] {subprocess.py:93} INFO - 2025-08-19 19:24:01,778 INFO Original target values before normalization: -0.601663    5163
[2025-08-19T19:24:01.779+0000] {subprocess.py:93} INFO -  1.662059    1869
[2025-08-19T19:24:01.781+0000] {subprocess.py:93} INFO - Name: Churn, dtype: int64
[2025-08-19T19:24:01.782+0000] {subprocess.py:93} INFO - 2025-08-19 19:24:01,778 INFO Original target dtype: float64
[2025-08-19T19:24:01.786+0000] {subprocess.py:93} INFO - 2025-08-19 19:24:01,780 INFO Unique numeric values in target: [-0.601663392508594, 1.6620589061112205]
[2025-08-19T19:24:01.802+0000] {subprocess.py:93} INFO - 2025-08-19 19:24:01,781 INFO Binary target with values [-0.601663392508594, 1.6620589061112205]. Mapping to (0,1).
[2025-08-19T19:24:01.806+0000] {subprocess.py:93} INFO - 2025-08-19 19:24:01,782 INFO Mapped -0.601663392508594→0, 1.6620589061112205→1
[2025-08-19T19:24:01.827+0000] {subprocess.py:93} INFO - 2025-08-19 19:24:01,784 INFO Final normalized target stats:
[2025-08-19T19:24:01.828+0000] {subprocess.py:93} INFO - 2025-08-19 19:24:01,785 INFO   - Unique values: [0, 1]
[2025-08-19T19:24:01.831+0000] {subprocess.py:93} INFO - 2025-08-19 19:24:01,787 INFO   - Value counts:
[2025-08-19T19:24:01.832+0000] {subprocess.py:93} INFO - 0    5163
[2025-08-19T19:24:01.833+0000] {subprocess.py:93} INFO - 1    1869
[2025-08-19T19:24:01.835+0000] {subprocess.py:93} INFO - Name: Churn, dtype: int64
[2025-08-19T19:24:01.836+0000] {subprocess.py:93} INFO - 2025-08-19 19:24:01,787 INFO Features shape before dtype fix: (7032, 35), Target shape: (7032,)
[2025-08-19T19:24:01.895+0000] {subprocess.py:93} INFO - 2025-08-19 19:24:01,894 INFO Features dtypes after fix:
[2025-08-19T19:24:01.907+0000] {subprocess.py:93} INFO - gender                                   float64
[2025-08-19T19:24:01.917+0000] {subprocess.py:93} INFO - SeniorCitizen                            float64
[2025-08-19T19:24:01.923+0000] {subprocess.py:93} INFO - Partner                                  float64
[2025-08-19T19:24:01.936+0000] {subprocess.py:93} INFO - Dependents                               float64
[2025-08-19T19:24:01.946+0000] {subprocess.py:93} INFO - tenure                                   float64
[2025-08-19T19:24:01.954+0000] {subprocess.py:93} INFO - PhoneService                             float64
[2025-08-19T19:24:01.963+0000] {subprocess.py:93} INFO - PaperlessBilling                         float64
[2025-08-19T19:24:01.969+0000] {subprocess.py:93} INFO - MonthlyCharges                           float64
[2025-08-19T19:24:01.972+0000] {subprocess.py:93} INFO - TotalCharges                             float64
[2025-08-19T19:24:01.976+0000] {subprocess.py:93} INFO - TotalChargesPerTenure                    float64
[2025-08-19T19:24:01.978+0000] {subprocess.py:93} INFO - MultipleLines_No phone service           float64
[2025-08-19T19:24:01.989+0000] {subprocess.py:93} INFO - MultipleLines_Yes                        float64
[2025-08-19T19:24:01.994+0000] {subprocess.py:93} INFO - InternetService_Fiber optic              float64
[2025-08-19T19:24:01.998+0000] {subprocess.py:93} INFO - InternetService_No                       float64
[2025-08-19T19:24:02.041+0000] {subprocess.py:93} INFO - OnlineSecurity_No internet service       float64
[2025-08-19T19:24:02.067+0000] {subprocess.py:93} INFO - OnlineSecurity_Yes                       float64
[2025-08-19T19:24:02.072+0000] {subprocess.py:93} INFO - OnlineBackup_No internet service         float64
[2025-08-19T19:24:02.074+0000] {subprocess.py:93} INFO - OnlineBackup_Yes                         float64
[2025-08-19T19:24:02.079+0000] {subprocess.py:93} INFO - DeviceProtection_No internet service     float64
[2025-08-19T19:24:02.085+0000] {subprocess.py:93} INFO - DeviceProtection_Yes                     float64
[2025-08-19T19:24:02.086+0000] {subprocess.py:93} INFO - TechSupport_No internet service          float64
[2025-08-19T19:24:02.089+0000] {subprocess.py:93} INFO - TechSupport_Yes                          float64
[2025-08-19T19:24:02.116+0000] {subprocess.py:93} INFO - StreamingTV_No internet service          float64
[2025-08-19T19:24:02.121+0000] {subprocess.py:93} INFO - StreamingTV_Yes                          float64
[2025-08-19T19:24:02.131+0000] {subprocess.py:93} INFO - StreamingMovies_No internet service      float64
[2025-08-19T19:24:02.136+0000] {subprocess.py:93} INFO - StreamingMovies_Yes                      float64
[2025-08-19T19:24:02.138+0000] {subprocess.py:93} INFO - Contract_One year                        float64
[2025-08-19T19:24:02.141+0000] {subprocess.py:93} INFO - Contract_Two year                        float64
[2025-08-19T19:24:02.142+0000] {subprocess.py:93} INFO - PaymentMethod_Credit card (automatic)    float64
[2025-08-19T19:24:02.144+0000] {subprocess.py:93} INFO - PaymentMethod_Electronic check           float64
[2025-08-19T19:24:02.146+0000] {subprocess.py:93} INFO - PaymentMethod_Mailed check               float64
[2025-08-19T19:24:02.148+0000] {subprocess.py:93} INFO - TenureGroup_13-24                        float64
[2025-08-19T19:24:02.150+0000] {subprocess.py:93} INFO - TenureGroup_25-48                        float64
[2025-08-19T19:24:02.151+0000] {subprocess.py:93} INFO - TenureGroup_49-60                        float64
[2025-08-19T19:24:02.154+0000] {subprocess.py:93} INFO - TenureGroup_61+                          float64
[2025-08-19T19:24:02.155+0000] {subprocess.py:93} INFO - dtype: object
[2025-08-19T19:24:02.165+0000] {subprocess.py:93} INFO - 2025-08-19 19:24:01,897 INFO Unique classes in target: [0 1]
[2025-08-19T19:24:02.170+0000] {subprocess.py:93} INFO - 2025-08-19 19:24:01,897 INFO Class distribution: [5163 1869]
[2025-08-19T19:24:05.585+0000] {subprocess.py:93} INFO - 2025-08-19 19:24:05,585 INFO Logistic Regression recall=0.7807, acc=0.7306, prec=0.4958, f1=0.6064
[2025-08-19T19:24:05.610+0000] {subprocess.py:93} INFO - 2025-08-19 19:24:05,610 INFO Classification report:
[2025-08-19T19:24:05.611+0000] {subprocess.py:93} INFO -               precision    recall  f1-score   support
[2025-08-19T19:24:05.612+0000] {subprocess.py:93} INFO - 
[2025-08-19T19:24:05.613+0000] {subprocess.py:93} INFO -            0       0.90      0.71      0.80      1033
[2025-08-19T19:24:05.614+0000] {subprocess.py:93} INFO -            1       0.50      0.78      0.61       374
[2025-08-19T19:24:05.615+0000] {subprocess.py:93} INFO - 
[2025-08-19T19:24:05.616+0000] {subprocess.py:93} INFO -     accuracy                           0.73      1407
[2025-08-19T19:24:05.617+0000] {subprocess.py:93} INFO -    macro avg       0.70      0.75      0.70      1407
[2025-08-19T19:24:05.618+0000] {subprocess.py:93} INFO - weighted avg       0.79      0.73      0.75      1407
[2025-08-19T19:24:05.619+0000] {subprocess.py:93} INFO - 
[2025-08-19T19:24:08.410+0000] {subprocess.py:93} INFO - 2025-08-19 19:24:08,410 INFO RandomForest recall=0.4733, acc=0.7953, prec=0.6604, f1=0.5514
[2025-08-19T19:24:08.423+0000] {subprocess.py:93} INFO - 2025-08-19 19:24:08,422 INFO Classification report:
[2025-08-19T19:24:08.424+0000] {subprocess.py:93} INFO -               precision    recall  f1-score   support
[2025-08-19T19:24:08.426+0000] {subprocess.py:93} INFO - 
[2025-08-19T19:24:08.427+0000] {subprocess.py:93} INFO -            0       0.83      0.91      0.87      1033
[2025-08-19T19:24:08.428+0000] {subprocess.py:93} INFO -            1       0.66      0.47      0.55       374
[2025-08-19T19:24:08.429+0000] {subprocess.py:93} INFO - 
[2025-08-19T19:24:08.430+0000] {subprocess.py:93} INFO -     accuracy                           0.80      1407
[2025-08-19T19:24:08.431+0000] {subprocess.py:93} INFO -    macro avg       0.74      0.69      0.71      1407
[2025-08-19T19:24:08.431+0000] {subprocess.py:93} INFO - weighted avg       0.78      0.80      0.78      1407
[2025-08-19T19:24:08.432+0000] {subprocess.py:93} INFO - 
[2025-08-19T19:24:08.509+0000] {subprocess.py:93} INFO - 2025-08-19 19:24:08,508 INFO Best model (LogisticRegression) saved locally to models/churn_model.pkl with recall=0.7807
[2025-08-19T19:24:08.511+0000] {subprocess.py:93} INFO - 2025-08-19 19:24:08,510 INFO Best run_id written to /tmp/best_run_id.txt
[2025-08-19T19:24:26.429+0000] {subprocess.py:93} INFO - /home/***/.local/lib/python3.8/site-packages/mlflow/types/utils.py:407: UserWarning: Hint: Inferred schema contains integer column(s). Integer columns in Python cannot represent missing values. If your input data contains missing values at inference time, it will be encoded as floats and will cause a schema enforcement error. The best way to avoid this problem is to infer the model schema based on a realistic data sample (training dataset) that includes missing values. Alternatively, you can declare integer columns as doubles (float64) whenever these columns may have missing values. See `Handling Integers With Missing Values <https://www.mlflow.org/docs/latest/models.html#handling-integers-with-missing-values>`_ for more details.
[2025-08-19T19:24:26.431+0000] {subprocess.py:93} INFO -   warnings.warn(
[2025-08-19T19:24:26.432+0000] {subprocess.py:93} INFO - Registered model 'churn_model' already exists. Creating a new version of this model...
[2025-08-19T19:24:26.433+0000] {subprocess.py:93} INFO - 2025-08-19 19:24:26,429 WARNING Model Version creation error (name=churn_model) Retrying 2 more times.
[2025-08-19T19:24:26.638+0000] {subprocess.py:93} INFO - 2025-08-19 19:24:26,638 WARNING Model Version creation error (name=churn_model) Retrying 1 more time.
[2025-08-19T19:24:26.848+0000] {subprocess.py:93} INFO - 2025-08-19 19:24:26,848 WARNING Model Version creation error (name=churn_model) Retrying 0 more time.
[2025-08-19T19:24:26.916+0000] {subprocess.py:93} INFO - 2025-08-19 19:24:26,916 WARNING MLflow model registry logging failed: Model Version creation error (name=churn_model). Error: [Errno 1] Operation not permitted. Giving up after 3 attempts.. Continuing with local model only.
[2025-08-19T19:24:27.572+0000] {subprocess.py:97} INFO - Command exited with return code 0
[2025-08-19T19:24:27.637+0000] {taskinstance.py:1149} INFO - Marking task as SUCCESS. dag_id=customer_churn_pipeline, task_id=model_training, execution_date=20250819T192242, start_date=20250819T192354, end_date=20250819T192427
[2025-08-19T19:24:27.697+0000] {local_task_job_runner.py:234} INFO - Task exited with return code 0
[2025-08-19T19:24:27.774+0000] {taskinstance.py:3312} INFO - 1 downstream tasks scheduled from follow-on schedule check
